{"level":"ERROR","location":"[symbol_to_hsmtoken:126] data_ws","message":"cannot access local variable 'hsm_symbol' where it is not associated with a value","timestamp":"2025-05-28 18:27:55,337+0530","service":"FyersDataSocket","exception":"Traceback (most recent call last):\n  File \"C:\\Users\\hithesh_sunkara\\AppData\\Roaming\\Python\\Python313\\site-packages\\fyers_apiv3\\FyersWebsocket\\data_ws.py\", line 115, in symbol_to_hsmtoken\n    datadict[hsm_symbol] = symbol\n             ^^^^^^^^^^\nUnboundLocalError: cannot access local variable 'hsm_symbol' where it is not associated with a value","exception_name":"UnboundLocalError"}
{"level":"ERROR","location":"[__symbol_conversion:1374] data_ws","message":"'NoneType' object is not subscriptable","timestamp":"2025-05-28 18:27:55,341+0530","service":"FyersDataSocket","exception":"Traceback (most recent call last):\n  File \"C:\\Users\\hithesh_sunkara\\AppData\\Roaming\\Python\\Python313\\site-packages\\fyers_apiv3\\FyersWebsocket\\data_ws.py\", line 1333, in __symbol_conversion\n    if symbol_value[3] != \"\":\n       ~~~~~~~~~~~~^^^\nTypeError: 'NoneType' object is not subscriptable","exception_name":"TypeError"}
{"level":"ERROR","location":"[<lambda>:1663] data_ws","message":"Connection to remote host was lost.","timestamp":"2025-05-28 19:06:02,275+0530","service":"FyersDataSocket"}
{"level":"ERROR","location":"[symbol_to_hsmtoken:126] data_ws","message":"cannot access local variable 'hsm_symbol' where it is not associated with a value","timestamp":"2025-05-28 19:06:09,761+0530","service":"FyersDataSocket","exception":"Traceback (most recent call last):\n  File \"C:\\Users\\hithesh_sunkara\\AppData\\Roaming\\Python\\Python313\\site-packages\\websocket\\_app.py\", line 428, in setSock\n    dispatcher.read(self.sock.sock, read, check)\n    ~~~~~~~~~~~~~~~^^^^^^^^^^^^^^^^^^^^^^^^^^^^^\n  File \"C:\\Users\\hithesh_sunkara\\AppData\\Roaming\\Python\\Python313\\site-packages\\websocket\\_app.py\", line 99, in read\n    if not read_callback():\n           ~~~~~~~~~~~~~^^\n  File \"C:\\Users\\hithesh_sunkara\\AppData\\Roaming\\Python\\Python313\\site-packages\\websocket\\_app.py\", line 442, in read\n    raise e\n  File \"C:\\Users\\hithesh_sunkara\\AppData\\Roaming\\Python\\Python313\\site-packages\\websocket\\_app.py\", line 437, in read\n    op_code, frame = self.sock.recv_data_frame(True)\n                     ~~~~~~~~~~~~~~~~~~~~~~~~~^^^^^^\n  File \"C:\\Users\\hithesh_sunkara\\AppData\\Roaming\\Python\\Python313\\site-packages\\websocket\\_core.py\", line 406, in recv_data_frame\n    frame = self.recv_frame()\n  File \"C:\\Users\\hithesh_sunkara\\AppData\\Roaming\\Python\\Python313\\site-packages\\websocket\\_core.py\", line 445, in recv_frame\n    return self.frame_buffer.recv_frame()\n           ~~~~~~~~~~~~~~~~~~~~~~~~~~~~^^\n  File \"C:\\Users\\hithesh_sunkara\\AppData\\Roaming\\Python\\Python313\\site-packages\\websocket\\_abnf.py\", line 338, in recv_frame\n    self.recv_header()\n    ~~~~~~~~~~~~~~~~^^\n  File \"C:\\Users\\hithesh_sunkara\\AppData\\Roaming\\Python\\Python313\\site-packages\\websocket\\_abnf.py\", line 294, in recv_header\n    header = self.recv_strict(2)\n  File \"C:\\Users\\hithesh_sunkara\\AppData\\Roaming\\Python\\Python313\\site-packages\\websocket\\_abnf.py\", line 373, in recv_strict\n    bytes_ = self.recv(min(16384, shortage))\n  File \"C:\\Users\\hithesh_sunkara\\AppData\\Roaming\\Python\\Python313\\site-packages\\websocket\\_core.py\", line 529, in _recv\n    return recv(self.sock, bufsize)\n  File \"C:\\Users\\hithesh_sunkara\\AppData\\Roaming\\Python\\Python313\\site-packages\\websocket\\_socket.py\", line 122, in recv\n    raise WebSocketConnectionClosedException(\n        \"Connection to remote host was lost.\")\nwebsocket._exceptions.WebSocketConnectionClosedException: Connection to remote host was lost.\n\nDuring handling of the above exception, another exception occurred:\n\nTraceback (most recent call last):\n  File \"C:\\Users\\hithesh_sunkara\\AppData\\Roaming\\Python\\Python313\\site-packages\\fyers_apiv3\\FyersWebsocket\\data_ws.py\", line 115, in symbol_to_hsmtoken\n    datadict[hsm_symbol] = symbol\n             ^^^^^^^^^^\nUnboundLocalError: cannot access local variable 'hsm_symbol' where it is not associated with a value","exception_name":"UnboundLocalError"}
{"level":"ERROR","location":"[__symbol_conversion:1374] data_ws","message":"'NoneType' object is not subscriptable","timestamp":"2025-05-28 19:06:09,772+0530","service":"FyersDataSocket","exception":"Traceback (most recent call last):\n  File \"C:\\Users\\hithesh_sunkara\\AppData\\Roaming\\Python\\Python313\\site-packages\\websocket\\_app.py\", line 428, in setSock\n    dispatcher.read(self.sock.sock, read, check)\n    ~~~~~~~~~~~~~~~^^^^^^^^^^^^^^^^^^^^^^^^^^^^^\n  File \"C:\\Users\\hithesh_sunkara\\AppData\\Roaming\\Python\\Python313\\site-packages\\websocket\\_app.py\", line 99, in read\n    if not read_callback():\n           ~~~~~~~~~~~~~^^\n  File \"C:\\Users\\hithesh_sunkara\\AppData\\Roaming\\Python\\Python313\\site-packages\\websocket\\_app.py\", line 442, in read\n    raise e\n  File \"C:\\Users\\hithesh_sunkara\\AppData\\Roaming\\Python\\Python313\\site-packages\\websocket\\_app.py\", line 437, in read\n    op_code, frame = self.sock.recv_data_frame(True)\n                     ~~~~~~~~~~~~~~~~~~~~~~~~~^^^^^^\n  File \"C:\\Users\\hithesh_sunkara\\AppData\\Roaming\\Python\\Python313\\site-packages\\websocket\\_core.py\", line 406, in recv_data_frame\n    frame = self.recv_frame()\n  File \"C:\\Users\\hithesh_sunkara\\AppData\\Roaming\\Python\\Python313\\site-packages\\websocket\\_core.py\", line 445, in recv_frame\n    return self.frame_buffer.recv_frame()\n           ~~~~~~~~~~~~~~~~~~~~~~~~~~~~^^\n  File \"C:\\Users\\hithesh_sunkara\\AppData\\Roaming\\Python\\Python313\\site-packages\\websocket\\_abnf.py\", line 338, in recv_frame\n    self.recv_header()\n    ~~~~~~~~~~~~~~~~^^\n  File \"C:\\Users\\hithesh_sunkara\\AppData\\Roaming\\Python\\Python313\\site-packages\\websocket\\_abnf.py\", line 294, in recv_header\n    header = self.recv_strict(2)\n  File \"C:\\Users\\hithesh_sunkara\\AppData\\Roaming\\Python\\Python313\\site-packages\\websocket\\_abnf.py\", line 373, in recv_strict\n    bytes_ = self.recv(min(16384, shortage))\n  File \"C:\\Users\\hithesh_sunkara\\AppData\\Roaming\\Python\\Python313\\site-packages\\websocket\\_core.py\", line 529, in _recv\n    return recv(self.sock, bufsize)\n  File \"C:\\Users\\hithesh_sunkara\\AppData\\Roaming\\Python\\Python313\\site-packages\\websocket\\_socket.py\", line 122, in recv\n    raise WebSocketConnectionClosedException(\n        \"Connection to remote host was lost.\")\nwebsocket._exceptions.WebSocketConnectionClosedException: Connection to remote host was lost.\n\nDuring handling of the above exception, another exception occurred:\n\nTraceback (most recent call last):\n  File \"C:\\Users\\hithesh_sunkara\\AppData\\Roaming\\Python\\Python313\\site-packages\\fyers_apiv3\\FyersWebsocket\\data_ws.py\", line 1333, in __symbol_conversion\n    if symbol_value[3] != \"\":\n       ~~~~~~~~~~~~^^^\nTypeError: 'NoneType' object is not subscriptable","exception_name":"TypeError"}
{"level":"ERROR","location":"[<lambda>:1663] data_ws","message":"Connection to remote host was lost.","timestamp":"2025-05-28 19:31:09,877+0530","service":"FyersDataSocket"}
{"level":"ERROR","location":"[symbol_to_hsmtoken:126] data_ws","message":"cannot access local variable 'hsm_symbol' where it is not associated with a value","timestamp":"2025-05-28 19:31:17,317+0530","service":"FyersDataSocket","exception":"Traceback (most recent call last):\n  File \"C:\\Users\\hithesh_sunkara\\AppData\\Roaming\\Python\\Python313\\site-packages\\websocket\\_app.py\", line 428, in setSock\n    dispatcher.read(self.sock.sock, read, check)\n    ~~~~~~~~~~~~~~~^^^^^^^^^^^^^^^^^^^^^^^^^^^^^\n  File \"C:\\Users\\hithesh_sunkara\\AppData\\Roaming\\Python\\Python313\\site-packages\\websocket\\_app.py\", line 99, in read\n    if not read_callback():\n           ~~~~~~~~~~~~~^^\n  File \"C:\\Users\\hithesh_sunkara\\AppData\\Roaming\\Python\\Python313\\site-packages\\websocket\\_app.py\", line 442, in read\n    raise e\n  File \"C:\\Users\\hithesh_sunkara\\AppData\\Roaming\\Python\\Python313\\site-packages\\websocket\\_app.py\", line 437, in read\n    op_code, frame = self.sock.recv_data_frame(True)\n                     ~~~~~~~~~~~~~~~~~~~~~~~~~^^^^^^\n  File \"C:\\Users\\hithesh_sunkara\\AppData\\Roaming\\Python\\Python313\\site-packages\\websocket\\_core.py\", line 406, in recv_data_frame\n    frame = self.recv_frame()\n  File \"C:\\Users\\hithesh_sunkara\\AppData\\Roaming\\Python\\Python313\\site-packages\\websocket\\_core.py\", line 445, in recv_frame\n    return self.frame_buffer.recv_frame()\n           ~~~~~~~~~~~~~~~~~~~~~~~~~~~~^^\n  File \"C:\\Users\\hithesh_sunkara\\AppData\\Roaming\\Python\\Python313\\site-packages\\websocket\\_abnf.py\", line 338, in recv_frame\n    self.recv_header()\n    ~~~~~~~~~~~~~~~~^^\n  File \"C:\\Users\\hithesh_sunkara\\AppData\\Roaming\\Python\\Python313\\site-packages\\websocket\\_abnf.py\", line 294, in recv_header\n    header = self.recv_strict(2)\n  File \"C:\\Users\\hithesh_sunkara\\AppData\\Roaming\\Python\\Python313\\site-packages\\websocket\\_abnf.py\", line 373, in recv_strict\n    bytes_ = self.recv(min(16384, shortage))\n  File \"C:\\Users\\hithesh_sunkara\\AppData\\Roaming\\Python\\Python313\\site-packages\\websocket\\_core.py\", line 529, in _recv\n    return recv(self.sock, bufsize)\n  File \"C:\\Users\\hithesh_sunkara\\AppData\\Roaming\\Python\\Python313\\site-packages\\websocket\\_socket.py\", line 122, in recv\n    raise WebSocketConnectionClosedException(\n        \"Connection to remote host was lost.\")\nwebsocket._exceptions.WebSocketConnectionClosedException: Connection to remote host was lost.\n\nDuring handling of the above exception, another exception occurred:\n\nTraceback (most recent call last):\n  File \"C:\\Users\\hithesh_sunkara\\AppData\\Roaming\\Python\\Python313\\site-packages\\fyers_apiv3\\FyersWebsocket\\data_ws.py\", line 115, in symbol_to_hsmtoken\n    datadict[hsm_symbol] = symbol\n             ^^^^^^^^^^\nUnboundLocalError: cannot access local variable 'hsm_symbol' where it is not associated with a value","exception_name":"UnboundLocalError"}
{"level":"ERROR","location":"[__symbol_conversion:1374] data_ws","message":"'NoneType' object is not subscriptable","timestamp":"2025-05-28 19:31:17,321+0530","service":"FyersDataSocket","exception":"Traceback (most recent call last):\n  File \"C:\\Users\\hithesh_sunkara\\AppData\\Roaming\\Python\\Python313\\site-packages\\websocket\\_app.py\", line 428, in setSock\n    dispatcher.read(self.sock.sock, read, check)\n    ~~~~~~~~~~~~~~~^^^^^^^^^^^^^^^^^^^^^^^^^^^^^\n  File \"C:\\Users\\hithesh_sunkara\\AppData\\Roaming\\Python\\Python313\\site-packages\\websocket\\_app.py\", line 99, in read\n    if not read_callback():\n           ~~~~~~~~~~~~~^^\n  File \"C:\\Users\\hithesh_sunkara\\AppData\\Roaming\\Python\\Python313\\site-packages\\websocket\\_app.py\", line 442, in read\n    raise e\n  File \"C:\\Users\\hithesh_sunkara\\AppData\\Roaming\\Python\\Python313\\site-packages\\websocket\\_app.py\", line 437, in read\n    op_code, frame = self.sock.recv_data_frame(True)\n                     ~~~~~~~~~~~~~~~~~~~~~~~~~^^^^^^\n  File \"C:\\Users\\hithesh_sunkara\\AppData\\Roaming\\Python\\Python313\\site-packages\\websocket\\_core.py\", line 406, in recv_data_frame\n    frame = self.recv_frame()\n  File \"C:\\Users\\hithesh_sunkara\\AppData\\Roaming\\Python\\Python313\\site-packages\\websocket\\_core.py\", line 445, in recv_frame\n    return self.frame_buffer.recv_frame()\n           ~~~~~~~~~~~~~~~~~~~~~~~~~~~~^^\n  File \"C:\\Users\\hithesh_sunkara\\AppData\\Roaming\\Python\\Python313\\site-packages\\websocket\\_abnf.py\", line 338, in recv_frame\n    self.recv_header()\n    ~~~~~~~~~~~~~~~~^^\n  File \"C:\\Users\\hithesh_sunkara\\AppData\\Roaming\\Python\\Python313\\site-packages\\websocket\\_abnf.py\", line 294, in recv_header\n    header = self.recv_strict(2)\n  File \"C:\\Users\\hithesh_sunkara\\AppData\\Roaming\\Python\\Python313\\site-packages\\websocket\\_abnf.py\", line 373, in recv_strict\n    bytes_ = self.recv(min(16384, shortage))\n  File \"C:\\Users\\hithesh_sunkara\\AppData\\Roaming\\Python\\Python313\\site-packages\\websocket\\_core.py\", line 529, in _recv\n    return recv(self.sock, bufsize)\n  File \"C:\\Users\\hithesh_sunkara\\AppData\\Roaming\\Python\\Python313\\site-packages\\websocket\\_socket.py\", line 122, in recv\n    raise WebSocketConnectionClosedException(\n        \"Connection to remote host was lost.\")\nwebsocket._exceptions.WebSocketConnectionClosedException: Connection to remote host was lost.\n\nDuring handling of the above exception, another exception occurred:\n\nTraceback (most recent call last):\n  File \"C:\\Users\\hithesh_sunkara\\AppData\\Roaming\\Python\\Python313\\site-packages\\fyers_apiv3\\FyersWebsocket\\data_ws.py\", line 1333, in __symbol_conversion\n    if symbol_value[3] != \"\":\n       ~~~~~~~~~~~~^^^\nTypeError: 'NoneType' object is not subscriptable","exception_name":"TypeError"}
{"level":"ERROR","location":"[<lambda>:1663] data_ws","message":"[WinError 10054] An existing connection was forcibly closed by the remote host","timestamp":"2025-05-28 21:50:13,045+0530","service":"FyersDataSocket"}
{"level":"ERROR","location":"[<lambda>:1663] data_ws","message":"[Errno 11001] getaddrinfo failed","timestamp":"2025-05-28 21:50:18,059+0530","service":"FyersDataSocket"}
{"level":"ERROR","location":"[symbol_to_hsmtoken:126] data_ws","message":"HTTPSConnectionPool(host='api-t1.fyers.in', port=443): Max retries exceeded with url: /data/symbol-token (Caused by NameResolutionError(\"<urllib3.connection.HTTPSConnection object at 0x000002084F40C690>: Failed to resolve 'api-t1.fyers.in' ([Errno 11001] getaddrinfo failed)\"))","timestamp":"2025-05-28 21:50:20,055+0530","service":"FyersDataSocket","exception":"Traceback (most recent call last):\n  File \"C:\\Users\\hithesh_sunkara\\AppData\\Roaming\\Python\\Python313\\site-packages\\websocket\\_app.py\", line 428, in setSock\n    dispatcher.read(self.sock.sock, read, check)\n    ~~~~~~~~~~~~~~~^^^^^^^^^^^^^^^^^^^^^^^^^^^^^\n  File \"C:\\Users\\hithesh_sunkara\\AppData\\Roaming\\Python\\Python313\\site-packages\\websocket\\_app.py\", line 99, in read\n    if not read_callback():\n           ~~~~~~~~~~~~~^^\n  File \"C:\\Users\\hithesh_sunkara\\AppData\\Roaming\\Python\\Python313\\site-packages\\websocket\\_app.py\", line 437, in read\n    op_code, frame = self.sock.recv_data_frame(True)\n                     ~~~~~~~~~~~~~~~~~~~~~~~~~^^^^^^\n  File \"C:\\Users\\hithesh_sunkara\\AppData\\Roaming\\Python\\Python313\\site-packages\\websocket\\_core.py\", line 406, in recv_data_frame\n    frame = self.recv_frame()\n  File \"C:\\Users\\hithesh_sunkara\\AppData\\Roaming\\Python\\Python313\\site-packages\\websocket\\_core.py\", line 445, in recv_frame\n    return self.frame_buffer.recv_frame()\n           ~~~~~~~~~~~~~~~~~~~~~~~~~~~~^^\n  File \"C:\\Users\\hithesh_sunkara\\AppData\\Roaming\\Python\\Python313\\site-packages\\websocket\\_abnf.py\", line 338, in recv_frame\n    self.recv_header()\n    ~~~~~~~~~~~~~~~~^^\n  File \"C:\\Users\\hithesh_sunkara\\AppData\\Roaming\\Python\\Python313\\site-packages\\websocket\\_abnf.py\", line 294, in recv_header\n    header = self.recv_strict(2)\n  File \"C:\\Users\\hithesh_sunkara\\AppData\\Roaming\\Python\\Python313\\site-packages\\websocket\\_abnf.py\", line 373, in recv_strict\n    bytes_ = self.recv(min(16384, shortage))\n  File \"C:\\Users\\hithesh_sunkara\\AppData\\Roaming\\Python\\Python313\\site-packages\\websocket\\_core.py\", line 529, in _recv\n    return recv(self.sock, bufsize)\n  File \"C:\\Users\\hithesh_sunkara\\AppData\\Roaming\\Python\\Python313\\site-packages\\websocket\\_socket.py\", line 108, in recv\n    bytes_ = _recv()\n  File \"C:\\Users\\hithesh_sunkara\\AppData\\Roaming\\Python\\Python313\\site-packages\\websocket\\_socket.py\", line 87, in _recv\n    return sock.recv(bufsize)\n           ~~~~~~~~~^^^^^^^^^\n  File \"C:\\Python313\\Lib\\ssl.py\", line 1285, in recv\n    return self.read(buflen)\n           ~~~~~~~~~^^^^^^^^\n  File \"C:\\Python313\\Lib\\ssl.py\", line 1140, in read\n    return self._sslobj.read(len)\n           ~~~~~~~~~~~~~~~~~^^^^^\nConnectionResetError: [WinError 10054] An existing connection was forcibly closed by the remote host\n\nDuring handling of the above exception, another exception occurred:\n\nTraceback (most recent call last):\n  File \"C:\\Users\\hithesh_sunkara\\AppData\\Roaming\\Python\\Python313\\site-packages\\urllib3\\connection.py\", line 198, in _new_conn\n    sock = connection.create_connection(\n        (self._dns_host, self.port),\n    ...<2 lines>...\n        socket_options=self.socket_options,\n    )\n  File \"C:\\Users\\hithesh_sunkara\\AppData\\Roaming\\Python\\Python313\\site-packages\\urllib3\\util\\connection.py\", line 60, in create_connection\n    for res in socket.getaddrinfo(host, port, family, socket.SOCK_STREAM):\n               ~~~~~~~~~~~~~~~~~~^^^^^^^^^^^^^^^^^^^^^^^^^^^^^^^^^^^^^^^^\n  File \"C:\\Python313\\Lib\\socket.py\", line 977, in getaddrinfo\n    for res in _socket.getaddrinfo(host, port, family, type, proto, flags):\n               ~~~~~~~~~~~~~~~~~~~^^^^^^^^^^^^^^^^^^^^^^^^^^^^^^^^^^^^^^^^\nsocket.gaierror: [Errno 11001] getaddrinfo failed\n\nThe above exception was the direct cause of the following exception:\n\nTraceback (most recent call last):\n  File \"C:\\Users\\hithesh_sunkara\\AppData\\Roaming\\Python\\Python313\\site-packages\\urllib3\\connectionpool.py\", line 787, in urlopen\n    response = self._make_request(\n        conn,\n    ...<10 lines>...\n        **response_kw,\n    )\n  File \"C:\\Users\\hithesh_sunkara\\AppData\\Roaming\\Python\\Python313\\site-packages\\urllib3\\connectionpool.py\", line 488, in _make_request\n    raise new_e\n  File \"C:\\Users\\hithesh_sunkara\\AppData\\Roaming\\Python\\Python313\\site-packages\\urllib3\\connectionpool.py\", line 464, in _make_request\n    self._validate_conn(conn)\n    ~~~~~~~~~~~~~~~~~~~^^^^^^\n  File \"C:\\Users\\hithesh_sunkara\\AppData\\Roaming\\Python\\Python313\\site-packages\\urllib3\\connectionpool.py\", line 1093, in _validate_conn\n    conn.connect()\n    ~~~~~~~~~~~~^^\n  File \"C:\\Users\\hithesh_sunkara\\AppData\\Roaming\\Python\\Python313\\site-packages\\urllib3\\connection.py\", line 704, in connect\n    self.sock = sock = self._new_conn()\n                       ~~~~~~~~~~~~~~^^\n  File \"C:\\Users\\hithesh_sunkara\\AppData\\Roaming\\Python\\Python313\\site-packages\\urllib3\\connection.py\", line 205, in _new_conn\n    raise NameResolutionError(self.host, self, e) from e\nurllib3.exceptions.NameResolutionError: <urllib3.connection.HTTPSConnection object at 0x000002084F40C690>: Failed to resolve 'api-t1.fyers.in' ([Errno 11001] getaddrinfo failed)\n\nThe above exception was the direct cause of the following exception:\n\nTraceback (most recent call last):\n  File \"C:\\Users\\hithesh_sunkara\\AppData\\Roaming\\Python\\Python313\\site-packages\\requests\\adapters.py\", line 486, in send\n    resp = conn.urlopen(\n        method=request.method,\n    ...<9 lines>...\n        chunked=chunked,\n    )\n  File \"C:\\Users\\hithesh_sunkara\\AppData\\Roaming\\Python\\Python313\\site-packages\\urllib3\\connectionpool.py\", line 841, in urlopen\n    retries = retries.increment(\n        method, url, error=new_e, _pool=self, _stacktrace=sys.exc_info()[2]\n    )\n  File \"C:\\Users\\hithesh_sunkara\\AppData\\Roaming\\Python\\Python313\\site-packages\\urllib3\\util\\retry.py\", line 519, in increment\n    raise MaxRetryError(_pool, url, reason) from reason  # type: ignore[arg-type]\n    ^^^^^^^^^^^^^^^^^^^^^^^^^^^^^^^^^^^^^^^^^^^^^^^^^^^\nurllib3.exceptions.MaxRetryError: HTTPSConnectionPool(host='api-t1.fyers.in', port=443): Max retries exceeded with url: /data/symbol-token (Caused by NameResolutionError(\"<urllib3.connection.HTTPSConnection object at 0x000002084F40C690>: Failed to resolve 'api-t1.fyers.in' ([Errno 11001] getaddrinfo failed)\"))\n\nDuring handling of the above exception, another exception occurred:\n\nTraceback (most recent call last):\n  File \"C:\\Users\\hithesh_sunkara\\AppData\\Roaming\\Python\\Python313\\site-packages\\fyers_apiv3\\FyersWebsocket\\data_ws.py\", line 63, in symbol_to_hsmtoken\n    response = requests.post(\n        url=self.symbols_token_api ,\n    ...<3 lines>...\n        },json=data\n    )\n  File \"C:\\Users\\hithesh_sunkara\\AppData\\Roaming\\Python\\Python313\\site-packages\\requests\\api.py\", line 115, in post\n    return request(\"post\", url, data=data, json=json, **kwargs)\n  File \"C:\\Users\\hithesh_sunkara\\AppData\\Roaming\\Python\\Python313\\site-packages\\requests\\api.py\", line 59, in request\n    return session.request(method=method, url=url, **kwargs)\n           ~~~~~~~~~~~~~~~^^^^^^^^^^^^^^^^^^^^^^^^^^^^^^^^^^\n  File \"C:\\Users\\hithesh_sunkara\\AppData\\Roaming\\Python\\Python313\\site-packages\\requests\\sessions.py\", line 589, in request\n    resp = self.send(prep, **send_kwargs)\n  File \"C:\\Users\\hithesh_sunkara\\AppData\\Roaming\\Python\\Python313\\site-packages\\requests\\sessions.py\", line 703, in send\n    r = adapter.send(request, **kwargs)\n  File \"C:\\Users\\hithesh_sunkara\\AppData\\Roaming\\Python\\Python313\\site-packages\\requests\\adapters.py\", line 519, in send\n    raise ConnectionError(e, request=request)\nrequests.exceptions.ConnectionError: HTTPSConnectionPool(host='api-t1.fyers.in', port=443): Max retries exceeded with url: /data/symbol-token (Caused by NameResolutionError(\"<urllib3.connection.HTTPSConnection object at 0x000002084F40C690>: Failed to resolve 'api-t1.fyers.in' ([Errno 11001] getaddrinfo failed)\"))","exception_name":"ConnectionError"}
{"level":"ERROR","location":"[__symbol_conversion:1374] data_ws","message":"'NoneType' object is not subscriptable","timestamp":"2025-05-28 21:50:20,086+0530","service":"FyersDataSocket","exception":"Traceback (most recent call last):\n  File \"C:\\Users\\hithesh_sunkara\\AppData\\Roaming\\Python\\Python313\\site-packages\\websocket\\_app.py\", line 428, in setSock\n    dispatcher.read(self.sock.sock, read, check)\n    ~~~~~~~~~~~~~~~^^^^^^^^^^^^^^^^^^^^^^^^^^^^^\n  File \"C:\\Users\\hithesh_sunkara\\AppData\\Roaming\\Python\\Python313\\site-packages\\websocket\\_app.py\", line 99, in read\n    if not read_callback():\n           ~~~~~~~~~~~~~^^\n  File \"C:\\Users\\hithesh_sunkara\\AppData\\Roaming\\Python\\Python313\\site-packages\\websocket\\_app.py\", line 437, in read\n    op_code, frame = self.sock.recv_data_frame(True)\n                     ~~~~~~~~~~~~~~~~~~~~~~~~~^^^^^^\n  File \"C:\\Users\\hithesh_sunkara\\AppData\\Roaming\\Python\\Python313\\site-packages\\websocket\\_core.py\", line 406, in recv_data_frame\n    frame = self.recv_frame()\n  File \"C:\\Users\\hithesh_sunkara\\AppData\\Roaming\\Python\\Python313\\site-packages\\websocket\\_core.py\", line 445, in recv_frame\n    return self.frame_buffer.recv_frame()\n           ~~~~~~~~~~~~~~~~~~~~~~~~~~~~^^\n  File \"C:\\Users\\hithesh_sunkara\\AppData\\Roaming\\Python\\Python313\\site-packages\\websocket\\_abnf.py\", line 338, in recv_frame\n    self.recv_header()\n    ~~~~~~~~~~~~~~~~^^\n  File \"C:\\Users\\hithesh_sunkara\\AppData\\Roaming\\Python\\Python313\\site-packages\\websocket\\_abnf.py\", line 294, in recv_header\n    header = self.recv_strict(2)\n  File \"C:\\Users\\hithesh_sunkara\\AppData\\Roaming\\Python\\Python313\\site-packages\\websocket\\_abnf.py\", line 373, in recv_strict\n    bytes_ = self.recv(min(16384, shortage))\n  File \"C:\\Users\\hithesh_sunkara\\AppData\\Roaming\\Python\\Python313\\site-packages\\websocket\\_core.py\", line 529, in _recv\n    return recv(self.sock, bufsize)\n  File \"C:\\Users\\hithesh_sunkara\\AppData\\Roaming\\Python\\Python313\\site-packages\\websocket\\_socket.py\", line 108, in recv\n    bytes_ = _recv()\n  File \"C:\\Users\\hithesh_sunkara\\AppData\\Roaming\\Python\\Python313\\site-packages\\websocket\\_socket.py\", line 87, in _recv\n    return sock.recv(bufsize)\n           ~~~~~~~~~^^^^^^^^^\n  File \"C:\\Python313\\Lib\\ssl.py\", line 1285, in recv\n    return self.read(buflen)\n           ~~~~~~~~~^^^^^^^^\n  File \"C:\\Python313\\Lib\\ssl.py\", line 1140, in read\n    return self._sslobj.read(len)\n           ~~~~~~~~~~~~~~~~~^^^^^\nConnectionResetError: [WinError 10054] An existing connection was forcibly closed by the remote host\n\nDuring handling of the above exception, another exception occurred:\n\nTraceback (most recent call last):\n  File \"C:\\Users\\hithesh_sunkara\\AppData\\Roaming\\Python\\Python313\\site-packages\\fyers_apiv3\\FyersWebsocket\\data_ws.py\", line 1333, in __symbol_conversion\n    if symbol_value[3] != \"\":\n       ~~~~~~~~~~~~^^^\nTypeError: 'NoneType' object is not subscriptable","exception_name":"TypeError"}
{"level":"ERROR","location":"[<lambda>:1663] data_ws","message":"[Errno 11001] getaddrinfo failed","timestamp":"2025-05-28 21:50:23,066+0530","service":"FyersDataSocket"}
{"level":"ERROR","location":"[symbol_to_hsmtoken:126] data_ws","message":"cannot access local variable 'hsm_symbol' where it is not associated with a value","timestamp":"2025-05-28 21:50:26,135+0530","service":"FyersDataSocket","exception":"Traceback (most recent call last):\n  File \"C:\\Users\\hithesh_sunkara\\AppData\\Roaming\\Python\\Python313\\site-packages\\websocket\\_http.py\", line 155, in _get_addrinfo_list\n    addrinfo_list = socket.getaddrinfo(\n        hostname, port, 0, socket.SOCK_STREAM, socket.SOL_TCP)\n  File \"C:\\Python313\\Lib\\socket.py\", line 977, in getaddrinfo\n    for res in _socket.getaddrinfo(host, port, family, type, proto, flags):\n               ~~~~~~~~~~~~~~~~~~~^^^^^^^^^^^^^^^^^^^^^^^^^^^^^^^^^^^^^^^^\nsocket.gaierror: [Errno 11001] getaddrinfo failed\n\nDuring handling of the above exception, another exception occurred:\n\nTraceback (most recent call last):\n  File \"C:\\Users\\hithesh_sunkara\\AppData\\Roaming\\Python\\Python313\\site-packages\\websocket\\_app.py\", line 412, in setSock\n    self.sock.connect(\n    ~~~~~~~~~~~~~~~~~^\n        self.url, header=self.header, cookie=self.cookie,\n        ^^^^^^^^^^^^^^^^^^^^^^^^^^^^^^^^^^^^^^^^^^^^^^^^^\n    ...<4 lines>...\n        host=host, origin=origin, suppress_origin=suppress_origin,\n        ^^^^^^^^^^^^^^^^^^^^^^^^^^^^^^^^^^^^^^^^^^^^^^^^^^^^^^^^^^\n        proxy_type=proxy_type, socket=self.prepared_socket)\n        ^^^^^^^^^^^^^^^^^^^^^^^^^^^^^^^^^^^^^^^^^^^^^^^^^^^\n  File \"C:\\Users\\hithesh_sunkara\\AppData\\Roaming\\Python\\Python313\\site-packages\\websocket\\_core.py\", line 249, in connect\n    self.sock, addrs = connect(url, self.sock_opt, proxy_info(**options),\n                       ~~~~~~~^^^^^^^^^^^^^^^^^^^^^^^^^^^^^^^^^^^^^^^^^^^\n                               options.pop('socket', None))\n                               ^^^^^^^^^^^^^^^^^^^^^^^^^^^^\n  File \"C:\\Users\\hithesh_sunkara\\AppData\\Roaming\\Python\\Python313\\site-packages\\websocket\\_http.py\", line 122, in connect\n    addrinfo_list, need_tunnel, auth = _get_addrinfo_list(\n                                       ~~~~~~~~~~~~~~~~~~^\n        hostname, port_from_url, is_secure, proxy)\n        ^^^^^^^^^^^^^^^^^^^^^^^^^^^^^^^^^^^^^^^^^^\n  File \"C:\\Users\\hithesh_sunkara\\AppData\\Roaming\\Python\\Python313\\site-packages\\websocket\\_http.py\", line 167, in _get_addrinfo_list\n    raise WebSocketAddressException(e)\nwebsocket._exceptions.WebSocketAddressException: [Errno 11001] getaddrinfo failed\n\nDuring handling of the above exception, another exception occurred:\n\nTraceback (most recent call last):\n  File \"C:\\Users\\hithesh_sunkara\\AppData\\Roaming\\Python\\Python313\\site-packages\\fyers_apiv3\\FyersWebsocket\\data_ws.py\", line 115, in symbol_to_hsmtoken\n    datadict[hsm_symbol] = symbol\n             ^^^^^^^^^^\nUnboundLocalError: cannot access local variable 'hsm_symbol' where it is not associated with a value","exception_name":"UnboundLocalError"}
{"level":"ERROR","location":"[__symbol_conversion:1374] data_ws","message":"'NoneType' object is not subscriptable","timestamp":"2025-05-28 21:50:26,183+0530","service":"FyersDataSocket","exception":"Traceback (most recent call last):\n  File \"C:\\Users\\hithesh_sunkara\\AppData\\Roaming\\Python\\Python313\\site-packages\\websocket\\_http.py\", line 155, in _get_addrinfo_list\n    addrinfo_list = socket.getaddrinfo(\n        hostname, port, 0, socket.SOCK_STREAM, socket.SOL_TCP)\n  File \"C:\\Python313\\Lib\\socket.py\", line 977, in getaddrinfo\n    for res in _socket.getaddrinfo(host, port, family, type, proto, flags):\n               ~~~~~~~~~~~~~~~~~~~^^^^^^^^^^^^^^^^^^^^^^^^^^^^^^^^^^^^^^^^\nsocket.gaierror: [Errno 11001] getaddrinfo failed\n\nDuring handling of the above exception, another exception occurred:\n\nTraceback (most recent call last):\n  File \"C:\\Users\\hithesh_sunkara\\AppData\\Roaming\\Python\\Python313\\site-packages\\websocket\\_app.py\", line 412, in setSock\n    self.sock.connect(\n    ~~~~~~~~~~~~~~~~~^\n        self.url, header=self.header, cookie=self.cookie,\n        ^^^^^^^^^^^^^^^^^^^^^^^^^^^^^^^^^^^^^^^^^^^^^^^^^\n    ...<4 lines>...\n        host=host, origin=origin, suppress_origin=suppress_origin,\n        ^^^^^^^^^^^^^^^^^^^^^^^^^^^^^^^^^^^^^^^^^^^^^^^^^^^^^^^^^^\n        proxy_type=proxy_type, socket=self.prepared_socket)\n        ^^^^^^^^^^^^^^^^^^^^^^^^^^^^^^^^^^^^^^^^^^^^^^^^^^^\n  File \"C:\\Users\\hithesh_sunkara\\AppData\\Roaming\\Python\\Python313\\site-packages\\websocket\\_core.py\", line 249, in connect\n    self.sock, addrs = connect(url, self.sock_opt, proxy_info(**options),\n                       ~~~~~~~^^^^^^^^^^^^^^^^^^^^^^^^^^^^^^^^^^^^^^^^^^^\n                               options.pop('socket', None))\n                               ^^^^^^^^^^^^^^^^^^^^^^^^^^^^\n  File \"C:\\Users\\hithesh_sunkara\\AppData\\Roaming\\Python\\Python313\\site-packages\\websocket\\_http.py\", line 122, in connect\n    addrinfo_list, need_tunnel, auth = _get_addrinfo_list(\n                                       ~~~~~~~~~~~~~~~~~~^\n        hostname, port_from_url, is_secure, proxy)\n        ^^^^^^^^^^^^^^^^^^^^^^^^^^^^^^^^^^^^^^^^^^\n  File \"C:\\Users\\hithesh_sunkara\\AppData\\Roaming\\Python\\Python313\\site-packages\\websocket\\_http.py\", line 167, in _get_addrinfo_list\n    raise WebSocketAddressException(e)\nwebsocket._exceptions.WebSocketAddressException: [Errno 11001] getaddrinfo failed\n\nDuring handling of the above exception, another exception occurred:\n\nTraceback (most recent call last):\n  File \"C:\\Users\\hithesh_sunkara\\AppData\\Roaming\\Python\\Python313\\site-packages\\fyers_apiv3\\FyersWebsocket\\data_ws.py\", line 1333, in __symbol_conversion\n    if symbol_value[3] != \"\":\n       ~~~~~~~~~~~~^^^\nTypeError: 'NoneType' object is not subscriptable","exception_name":"TypeError"}
{"level":"ERROR","location":"[symbol_to_hsmtoken:126] data_ws","message":"cannot access local variable 'hsm_symbol' where it is not associated with a value","timestamp":"2025-05-28 21:50:31,007+0530","service":"FyersDataSocket","exception":"Traceback (most recent call last):\n  File \"C:\\Users\\hithesh_sunkara\\AppData\\Roaming\\Python\\Python313\\site-packages\\websocket\\_http.py\", line 155, in _get_addrinfo_list\n    addrinfo_list = socket.getaddrinfo(\n        hostname, port, 0, socket.SOCK_STREAM, socket.SOL_TCP)\n  File \"C:\\Python313\\Lib\\socket.py\", line 977, in getaddrinfo\n    for res in _socket.getaddrinfo(host, port, family, type, proto, flags):\n               ~~~~~~~~~~~~~~~~~~~^^^^^^^^^^^^^^^^^^^^^^^^^^^^^^^^^^^^^^^^\nsocket.gaierror: [Errno 11001] getaddrinfo failed\n\nDuring handling of the above exception, another exception occurred:\n\nTraceback (most recent call last):\n  File \"C:\\Users\\hithesh_sunkara\\AppData\\Roaming\\Python\\Python313\\site-packages\\websocket\\_app.py\", line 412, in setSock\n    self.sock.connect(\n    ~~~~~~~~~~~~~~~~~^\n        self.url, header=self.header, cookie=self.cookie,\n        ^^^^^^^^^^^^^^^^^^^^^^^^^^^^^^^^^^^^^^^^^^^^^^^^^\n    ...<4 lines>...\n        host=host, origin=origin, suppress_origin=suppress_origin,\n        ^^^^^^^^^^^^^^^^^^^^^^^^^^^^^^^^^^^^^^^^^^^^^^^^^^^^^^^^^^\n        proxy_type=proxy_type, socket=self.prepared_socket)\n        ^^^^^^^^^^^^^^^^^^^^^^^^^^^^^^^^^^^^^^^^^^^^^^^^^^^\n  File \"C:\\Users\\hithesh_sunkara\\AppData\\Roaming\\Python\\Python313\\site-packages\\websocket\\_core.py\", line 249, in connect\n    self.sock, addrs = connect(url, self.sock_opt, proxy_info(**options),\n                       ~~~~~~~^^^^^^^^^^^^^^^^^^^^^^^^^^^^^^^^^^^^^^^^^^^\n                               options.pop('socket', None))\n                               ^^^^^^^^^^^^^^^^^^^^^^^^^^^^\n  File \"C:\\Users\\hithesh_sunkara\\AppData\\Roaming\\Python\\Python313\\site-packages\\websocket\\_http.py\", line 122, in connect\n    addrinfo_list, need_tunnel, auth = _get_addrinfo_list(\n                                       ~~~~~~~~~~~~~~~~~~^\n        hostname, port_from_url, is_secure, proxy)\n        ^^^^^^^^^^^^^^^^^^^^^^^^^^^^^^^^^^^^^^^^^^\n  File \"C:\\Users\\hithesh_sunkara\\AppData\\Roaming\\Python\\Python313\\site-packages\\websocket\\_http.py\", line 167, in _get_addrinfo_list\n    raise WebSocketAddressException(e)\nwebsocket._exceptions.WebSocketAddressException: [Errno 11001] getaddrinfo failed\n\nDuring handling of the above exception, another exception occurred:\n\nTraceback (most recent call last):\n  File \"C:\\Users\\hithesh_sunkara\\AppData\\Roaming\\Python\\Python313\\site-packages\\fyers_apiv3\\FyersWebsocket\\data_ws.py\", line 115, in symbol_to_hsmtoken\n    datadict[hsm_symbol] = symbol\n             ^^^^^^^^^^\nUnboundLocalError: cannot access local variable 'hsm_symbol' where it is not associated with a value","exception_name":"UnboundLocalError"}
{"level":"ERROR","location":"[__symbol_conversion:1374] data_ws","message":"'NoneType' object is not subscriptable","timestamp":"2025-05-28 21:50:31,015+0530","service":"FyersDataSocket","exception":"Traceback (most recent call last):\n  File \"C:\\Users\\hithesh_sunkara\\AppData\\Roaming\\Python\\Python313\\site-packages\\websocket\\_http.py\", line 155, in _get_addrinfo_list\n    addrinfo_list = socket.getaddrinfo(\n        hostname, port, 0, socket.SOCK_STREAM, socket.SOL_TCP)\n  File \"C:\\Python313\\Lib\\socket.py\", line 977, in getaddrinfo\n    for res in _socket.getaddrinfo(host, port, family, type, proto, flags):\n               ~~~~~~~~~~~~~~~~~~~^^^^^^^^^^^^^^^^^^^^^^^^^^^^^^^^^^^^^^^^\nsocket.gaierror: [Errno 11001] getaddrinfo failed\n\nDuring handling of the above exception, another exception occurred:\n\nTraceback (most recent call last):\n  File \"C:\\Users\\hithesh_sunkara\\AppData\\Roaming\\Python\\Python313\\site-packages\\websocket\\_app.py\", line 412, in setSock\n    self.sock.connect(\n    ~~~~~~~~~~~~~~~~~^\n        self.url, header=self.header, cookie=self.cookie,\n        ^^^^^^^^^^^^^^^^^^^^^^^^^^^^^^^^^^^^^^^^^^^^^^^^^\n    ...<4 lines>...\n        host=host, origin=origin, suppress_origin=suppress_origin,\n        ^^^^^^^^^^^^^^^^^^^^^^^^^^^^^^^^^^^^^^^^^^^^^^^^^^^^^^^^^^\n        proxy_type=proxy_type, socket=self.prepared_socket)\n        ^^^^^^^^^^^^^^^^^^^^^^^^^^^^^^^^^^^^^^^^^^^^^^^^^^^\n  File \"C:\\Users\\hithesh_sunkara\\AppData\\Roaming\\Python\\Python313\\site-packages\\websocket\\_core.py\", line 249, in connect\n    self.sock, addrs = connect(url, self.sock_opt, proxy_info(**options),\n                       ~~~~~~~^^^^^^^^^^^^^^^^^^^^^^^^^^^^^^^^^^^^^^^^^^^\n                               options.pop('socket', None))\n                               ^^^^^^^^^^^^^^^^^^^^^^^^^^^^\n  File \"C:\\Users\\hithesh_sunkara\\AppData\\Roaming\\Python\\Python313\\site-packages\\websocket\\_http.py\", line 122, in connect\n    addrinfo_list, need_tunnel, auth = _get_addrinfo_list(\n                                       ~~~~~~~~~~~~~~~~~~^\n        hostname, port_from_url, is_secure, proxy)\n        ^^^^^^^^^^^^^^^^^^^^^^^^^^^^^^^^^^^^^^^^^^\n  File \"C:\\Users\\hithesh_sunkara\\AppData\\Roaming\\Python\\Python313\\site-packages\\websocket\\_http.py\", line 167, in _get_addrinfo_list\n    raise WebSocketAddressException(e)\nwebsocket._exceptions.WebSocketAddressException: [Errno 11001] getaddrinfo failed\n\nDuring handling of the above exception, another exception occurred:\n\nTraceback (most recent call last):\n  File \"C:\\Users\\hithesh_sunkara\\AppData\\Roaming\\Python\\Python313\\site-packages\\fyers_apiv3\\FyersWebsocket\\data_ws.py\", line 1333, in __symbol_conversion\n    if symbol_value[3] != \"\":\n       ~~~~~~~~~~~~^^^\nTypeError: 'NoneType' object is not subscriptable","exception_name":"TypeError"}
{"level":"ERROR","location":"[<lambda>:1663] data_ws","message":"[WinError 10054] An existing connection was forcibly closed by the remote host","timestamp":"2025-05-28 22:37:28,440+0530","service":"FyersDataSocket"}
{"level":"ERROR","location":"[<lambda>:1663] data_ws","message":"[Errno 11001] getaddrinfo failed","timestamp":"2025-05-28 22:37:33,464+0530","service":"FyersDataSocket"}
{"level":"ERROR","location":"[symbol_to_hsmtoken:126] data_ws","message":"HTTPSConnectionPool(host='api-t1.fyers.in', port=443): Max retries exceeded with url: /data/symbol-token (Caused by NameResolutionError(\"<urllib3.connection.HTTPSConnection object at 0x000002084F40D450>: Failed to resolve 'api-t1.fyers.in' ([Errno 11001] getaddrinfo failed)\"))","timestamp":"2025-05-28 22:37:35,473+0530","service":"FyersDataSocket","exception":"Traceback (most recent call last):\n  File \"C:\\Users\\hithesh_sunkara\\AppData\\Roaming\\Python\\Python313\\site-packages\\websocket\\_app.py\", line 428, in setSock\n    dispatcher.read(self.sock.sock, read, check)\n    ~~~~~~~~~~~~~~~^^^^^^^^^^^^^^^^^^^^^^^^^^^^^\n  File \"C:\\Users\\hithesh_sunkara\\AppData\\Roaming\\Python\\Python313\\site-packages\\websocket\\_app.py\", line 99, in read\n    if not read_callback():\n           ~~~~~~~~~~~~~^^\n  File \"C:\\Users\\hithesh_sunkara\\AppData\\Roaming\\Python\\Python313\\site-packages\\websocket\\_app.py\", line 437, in read\n    op_code, frame = self.sock.recv_data_frame(True)\n                     ~~~~~~~~~~~~~~~~~~~~~~~~~^^^^^^\n  File \"C:\\Users\\hithesh_sunkara\\AppData\\Roaming\\Python\\Python313\\site-packages\\websocket\\_core.py\", line 406, in recv_data_frame\n    frame = self.recv_frame()\n  File \"C:\\Users\\hithesh_sunkara\\AppData\\Roaming\\Python\\Python313\\site-packages\\websocket\\_core.py\", line 445, in recv_frame\n    return self.frame_buffer.recv_frame()\n           ~~~~~~~~~~~~~~~~~~~~~~~~~~~~^^\n  File \"C:\\Users\\hithesh_sunkara\\AppData\\Roaming\\Python\\Python313\\site-packages\\websocket\\_abnf.py\", line 338, in recv_frame\n    self.recv_header()\n    ~~~~~~~~~~~~~~~~^^\n  File \"C:\\Users\\hithesh_sunkara\\AppData\\Roaming\\Python\\Python313\\site-packages\\websocket\\_abnf.py\", line 294, in recv_header\n    header = self.recv_strict(2)\n  File \"C:\\Users\\hithesh_sunkara\\AppData\\Roaming\\Python\\Python313\\site-packages\\websocket\\_abnf.py\", line 373, in recv_strict\n    bytes_ = self.recv(min(16384, shortage))\n  File \"C:\\Users\\hithesh_sunkara\\AppData\\Roaming\\Python\\Python313\\site-packages\\websocket\\_core.py\", line 529, in _recv\n    return recv(self.sock, bufsize)\n  File \"C:\\Users\\hithesh_sunkara\\AppData\\Roaming\\Python\\Python313\\site-packages\\websocket\\_socket.py\", line 108, in recv\n    bytes_ = _recv()\n  File \"C:\\Users\\hithesh_sunkara\\AppData\\Roaming\\Python\\Python313\\site-packages\\websocket\\_socket.py\", line 87, in _recv\n    return sock.recv(bufsize)\n           ~~~~~~~~~^^^^^^^^^\n  File \"C:\\Python313\\Lib\\ssl.py\", line 1285, in recv\n    return self.read(buflen)\n           ~~~~~~~~~^^^^^^^^\n  File \"C:\\Python313\\Lib\\ssl.py\", line 1140, in read\n    return self._sslobj.read(len)\n           ~~~~~~~~~~~~~~~~~^^^^^\nConnectionResetError: [WinError 10054] An existing connection was forcibly closed by the remote host\n\nDuring handling of the above exception, another exception occurred:\n\nTraceback (most recent call last):\n  File \"C:\\Users\\hithesh_sunkara\\AppData\\Roaming\\Python\\Python313\\site-packages\\urllib3\\connection.py\", line 198, in _new_conn\n    sock = connection.create_connection(\n        (self._dns_host, self.port),\n    ...<2 lines>...\n        socket_options=self.socket_options,\n    )\n  File \"C:\\Users\\hithesh_sunkara\\AppData\\Roaming\\Python\\Python313\\site-packages\\urllib3\\util\\connection.py\", line 60, in create_connection\n    for res in socket.getaddrinfo(host, port, family, socket.SOCK_STREAM):\n               ~~~~~~~~~~~~~~~~~~^^^^^^^^^^^^^^^^^^^^^^^^^^^^^^^^^^^^^^^^\n  File \"C:\\Python313\\Lib\\socket.py\", line 977, in getaddrinfo\n    for res in _socket.getaddrinfo(host, port, family, type, proto, flags):\n               ~~~~~~~~~~~~~~~~~~~^^^^^^^^^^^^^^^^^^^^^^^^^^^^^^^^^^^^^^^^\nsocket.gaierror: [Errno 11001] getaddrinfo failed\n\nThe above exception was the direct cause of the following exception:\n\nTraceback (most recent call last):\n  File \"C:\\Users\\hithesh_sunkara\\AppData\\Roaming\\Python\\Python313\\site-packages\\urllib3\\connectionpool.py\", line 787, in urlopen\n    response = self._make_request(\n        conn,\n    ...<10 lines>...\n        **response_kw,\n    )\n  File \"C:\\Users\\hithesh_sunkara\\AppData\\Roaming\\Python\\Python313\\site-packages\\urllib3\\connectionpool.py\", line 488, in _make_request\n    raise new_e\n  File \"C:\\Users\\hithesh_sunkara\\AppData\\Roaming\\Python\\Python313\\site-packages\\urllib3\\connectionpool.py\", line 464, in _make_request\n    self._validate_conn(conn)\n    ~~~~~~~~~~~~~~~~~~~^^^^^^\n  File \"C:\\Users\\hithesh_sunkara\\AppData\\Roaming\\Python\\Python313\\site-packages\\urllib3\\connectionpool.py\", line 1093, in _validate_conn\n    conn.connect()\n    ~~~~~~~~~~~~^^\n  File \"C:\\Users\\hithesh_sunkara\\AppData\\Roaming\\Python\\Python313\\site-packages\\urllib3\\connection.py\", line 704, in connect\n    self.sock = sock = self._new_conn()\n                       ~~~~~~~~~~~~~~^^\n  File \"C:\\Users\\hithesh_sunkara\\AppData\\Roaming\\Python\\Python313\\site-packages\\urllib3\\connection.py\", line 205, in _new_conn\n    raise NameResolutionError(self.host, self, e) from e\nurllib3.exceptions.NameResolutionError: <urllib3.connection.HTTPSConnection object at 0x000002084F40D450>: Failed to resolve 'api-t1.fyers.in' ([Errno 11001] getaddrinfo failed)\n\nThe above exception was the direct cause of the following exception:\n\nTraceback (most recent call last):\n  File \"C:\\Users\\hithesh_sunkara\\AppData\\Roaming\\Python\\Python313\\site-packages\\requests\\adapters.py\", line 486, in send\n    resp = conn.urlopen(\n        method=request.method,\n    ...<9 lines>...\n        chunked=chunked,\n    )\n  File \"C:\\Users\\hithesh_sunkara\\AppData\\Roaming\\Python\\Python313\\site-packages\\urllib3\\connectionpool.py\", line 841, in urlopen\n    retries = retries.increment(\n        method, url, error=new_e, _pool=self, _stacktrace=sys.exc_info()[2]\n    )\n  File \"C:\\Users\\hithesh_sunkara\\AppData\\Roaming\\Python\\Python313\\site-packages\\urllib3\\util\\retry.py\", line 519, in increment\n    raise MaxRetryError(_pool, url, reason) from reason  # type: ignore[arg-type]\n    ^^^^^^^^^^^^^^^^^^^^^^^^^^^^^^^^^^^^^^^^^^^^^^^^^^^\nurllib3.exceptions.MaxRetryError: HTTPSConnectionPool(host='api-t1.fyers.in', port=443): Max retries exceeded with url: /data/symbol-token (Caused by NameResolutionError(\"<urllib3.connection.HTTPSConnection object at 0x000002084F40D450>: Failed to resolve 'api-t1.fyers.in' ([Errno 11001] getaddrinfo failed)\"))\n\nDuring handling of the above exception, another exception occurred:\n\nTraceback (most recent call last):\n  File \"C:\\Users\\hithesh_sunkara\\AppData\\Roaming\\Python\\Python313\\site-packages\\fyers_apiv3\\FyersWebsocket\\data_ws.py\", line 63, in symbol_to_hsmtoken\n    response = requests.post(\n        url=self.symbols_token_api ,\n    ...<3 lines>...\n        },json=data\n    )\n  File \"C:\\Users\\hithesh_sunkara\\AppData\\Roaming\\Python\\Python313\\site-packages\\requests\\api.py\", line 115, in post\n    return request(\"post\", url, data=data, json=json, **kwargs)\n  File \"C:\\Users\\hithesh_sunkara\\AppData\\Roaming\\Python\\Python313\\site-packages\\requests\\api.py\", line 59, in request\n    return session.request(method=method, url=url, **kwargs)\n           ~~~~~~~~~~~~~~~^^^^^^^^^^^^^^^^^^^^^^^^^^^^^^^^^^\n  File \"C:\\Users\\hithesh_sunkara\\AppData\\Roaming\\Python\\Python313\\site-packages\\requests\\sessions.py\", line 589, in request\n    resp = self.send(prep, **send_kwargs)\n  File \"C:\\Users\\hithesh_sunkara\\AppData\\Roaming\\Python\\Python313\\site-packages\\requests\\sessions.py\", line 703, in send\n    r = adapter.send(request, **kwargs)\n  File \"C:\\Users\\hithesh_sunkara\\AppData\\Roaming\\Python\\Python313\\site-packages\\requests\\adapters.py\", line 519, in send\n    raise ConnectionError(e, request=request)\nrequests.exceptions.ConnectionError: HTTPSConnectionPool(host='api-t1.fyers.in', port=443): Max retries exceeded with url: /data/symbol-token (Caused by NameResolutionError(\"<urllib3.connection.HTTPSConnection object at 0x000002084F40D450>: Failed to resolve 'api-t1.fyers.in' ([Errno 11001] getaddrinfo failed)\"))","exception_name":"ConnectionError"}
{"level":"ERROR","location":"[__symbol_conversion:1374] data_ws","message":"'NoneType' object is not subscriptable","timestamp":"2025-05-28 22:37:35,484+0530","service":"FyersDataSocket","exception":"Traceback (most recent call last):\n  File \"C:\\Users\\hithesh_sunkara\\AppData\\Roaming\\Python\\Python313\\site-packages\\websocket\\_app.py\", line 428, in setSock\n    dispatcher.read(self.sock.sock, read, check)\n    ~~~~~~~~~~~~~~~^^^^^^^^^^^^^^^^^^^^^^^^^^^^^\n  File \"C:\\Users\\hithesh_sunkara\\AppData\\Roaming\\Python\\Python313\\site-packages\\websocket\\_app.py\", line 99, in read\n    if not read_callback():\n           ~~~~~~~~~~~~~^^\n  File \"C:\\Users\\hithesh_sunkara\\AppData\\Roaming\\Python\\Python313\\site-packages\\websocket\\_app.py\", line 437, in read\n    op_code, frame = self.sock.recv_data_frame(True)\n                     ~~~~~~~~~~~~~~~~~~~~~~~~~^^^^^^\n  File \"C:\\Users\\hithesh_sunkara\\AppData\\Roaming\\Python\\Python313\\site-packages\\websocket\\_core.py\", line 406, in recv_data_frame\n    frame = self.recv_frame()\n  File \"C:\\Users\\hithesh_sunkara\\AppData\\Roaming\\Python\\Python313\\site-packages\\websocket\\_core.py\", line 445, in recv_frame\n    return self.frame_buffer.recv_frame()\n           ~~~~~~~~~~~~~~~~~~~~~~~~~~~~^^\n  File \"C:\\Users\\hithesh_sunkara\\AppData\\Roaming\\Python\\Python313\\site-packages\\websocket\\_abnf.py\", line 338, in recv_frame\n    self.recv_header()\n    ~~~~~~~~~~~~~~~~^^\n  File \"C:\\Users\\hithesh_sunkara\\AppData\\Roaming\\Python\\Python313\\site-packages\\websocket\\_abnf.py\", line 294, in recv_header\n    header = self.recv_strict(2)\n  File \"C:\\Users\\hithesh_sunkara\\AppData\\Roaming\\Python\\Python313\\site-packages\\websocket\\_abnf.py\", line 373, in recv_strict\n    bytes_ = self.recv(min(16384, shortage))\n  File \"C:\\Users\\hithesh_sunkara\\AppData\\Roaming\\Python\\Python313\\site-packages\\websocket\\_core.py\", line 529, in _recv\n    return recv(self.sock, bufsize)\n  File \"C:\\Users\\hithesh_sunkara\\AppData\\Roaming\\Python\\Python313\\site-packages\\websocket\\_socket.py\", line 108, in recv\n    bytes_ = _recv()\n  File \"C:\\Users\\hithesh_sunkara\\AppData\\Roaming\\Python\\Python313\\site-packages\\websocket\\_socket.py\", line 87, in _recv\n    return sock.recv(bufsize)\n           ~~~~~~~~~^^^^^^^^^\n  File \"C:\\Python313\\Lib\\ssl.py\", line 1285, in recv\n    return self.read(buflen)\n           ~~~~~~~~~^^^^^^^^\n  File \"C:\\Python313\\Lib\\ssl.py\", line 1140, in read\n    return self._sslobj.read(len)\n           ~~~~~~~~~~~~~~~~~^^^^^\nConnectionResetError: [WinError 10054] An existing connection was forcibly closed by the remote host\n\nDuring handling of the above exception, another exception occurred:\n\nTraceback (most recent call last):\n  File \"C:\\Users\\hithesh_sunkara\\AppData\\Roaming\\Python\\Python313\\site-packages\\fyers_apiv3\\FyersWebsocket\\data_ws.py\", line 1333, in __symbol_conversion\n    if symbol_value[3] != \"\":\n       ~~~~~~~~~~~~^^^\nTypeError: 'NoneType' object is not subscriptable","exception_name":"TypeError"}
{"level":"ERROR","location":"[<lambda>:1663] data_ws","message":"[Errno 11001] getaddrinfo failed","timestamp":"2025-05-28 22:37:38,468+0530","service":"FyersDataSocket"}
{"level":"ERROR","location":"[symbol_to_hsmtoken:126] data_ws","message":"HTTPSConnectionPool(host='api-t1.fyers.in', port=443): Max retries exceeded with url: /data/symbol-token (Caused by NameResolutionError(\"<urllib3.connection.HTTPSConnection object at 0x000002084F40C910>: Failed to resolve 'api-t1.fyers.in' ([Errno 11001] getaddrinfo failed)\"))","timestamp":"2025-05-28 22:37:40,473+0530","service":"FyersDataSocket","exception":"Traceback (most recent call last):\n  File \"C:\\Users\\hithesh_sunkara\\AppData\\Roaming\\Python\\Python313\\site-packages\\websocket\\_http.py\", line 155, in _get_addrinfo_list\n    addrinfo_list = socket.getaddrinfo(\n        hostname, port, 0, socket.SOCK_STREAM, socket.SOL_TCP)\n  File \"C:\\Python313\\Lib\\socket.py\", line 977, in getaddrinfo\n    for res in _socket.getaddrinfo(host, port, family, type, proto, flags):\n               ~~~~~~~~~~~~~~~~~~~^^^^^^^^^^^^^^^^^^^^^^^^^^^^^^^^^^^^^^^^\nsocket.gaierror: [Errno 11001] getaddrinfo failed\n\nDuring handling of the above exception, another exception occurred:\n\nTraceback (most recent call last):\n  File \"C:\\Users\\hithesh_sunkara\\AppData\\Roaming\\Python\\Python313\\site-packages\\websocket\\_app.py\", line 412, in setSock\n    self.sock.connect(\n    ~~~~~~~~~~~~~~~~~^\n        self.url, header=self.header, cookie=self.cookie,\n        ^^^^^^^^^^^^^^^^^^^^^^^^^^^^^^^^^^^^^^^^^^^^^^^^^\n    ...<4 lines>...\n        host=host, origin=origin, suppress_origin=suppress_origin,\n        ^^^^^^^^^^^^^^^^^^^^^^^^^^^^^^^^^^^^^^^^^^^^^^^^^^^^^^^^^^\n        proxy_type=proxy_type, socket=self.prepared_socket)\n        ^^^^^^^^^^^^^^^^^^^^^^^^^^^^^^^^^^^^^^^^^^^^^^^^^^^\n  File \"C:\\Users\\hithesh_sunkara\\AppData\\Roaming\\Python\\Python313\\site-packages\\websocket\\_core.py\", line 249, in connect\n    self.sock, addrs = connect(url, self.sock_opt, proxy_info(**options),\n                       ~~~~~~~^^^^^^^^^^^^^^^^^^^^^^^^^^^^^^^^^^^^^^^^^^^\n                               options.pop('socket', None))\n                               ^^^^^^^^^^^^^^^^^^^^^^^^^^^^\n  File \"C:\\Users\\hithesh_sunkara\\AppData\\Roaming\\Python\\Python313\\site-packages\\websocket\\_http.py\", line 122, in connect\n    addrinfo_list, need_tunnel, auth = _get_addrinfo_list(\n                                       ~~~~~~~~~~~~~~~~~~^\n        hostname, port_from_url, is_secure, proxy)\n        ^^^^^^^^^^^^^^^^^^^^^^^^^^^^^^^^^^^^^^^^^^\n  File \"C:\\Users\\hithesh_sunkara\\AppData\\Roaming\\Python\\Python313\\site-packages\\websocket\\_http.py\", line 167, in _get_addrinfo_list\n    raise WebSocketAddressException(e)\nwebsocket._exceptions.WebSocketAddressException: [Errno 11001] getaddrinfo failed\n\nDuring handling of the above exception, another exception occurred:\n\nTraceback (most recent call last):\n  File \"C:\\Users\\hithesh_sunkara\\AppData\\Roaming\\Python\\Python313\\site-packages\\urllib3\\connection.py\", line 198, in _new_conn\n    sock = connection.create_connection(\n        (self._dns_host, self.port),\n    ...<2 lines>...\n        socket_options=self.socket_options,\n    )\n  File \"C:\\Users\\hithesh_sunkara\\AppData\\Roaming\\Python\\Python313\\site-packages\\urllib3\\util\\connection.py\", line 60, in create_connection\n    for res in socket.getaddrinfo(host, port, family, socket.SOCK_STREAM):\n               ~~~~~~~~~~~~~~~~~~^^^^^^^^^^^^^^^^^^^^^^^^^^^^^^^^^^^^^^^^\n  File \"C:\\Python313\\Lib\\socket.py\", line 977, in getaddrinfo\n    for res in _socket.getaddrinfo(host, port, family, type, proto, flags):\n               ~~~~~~~~~~~~~~~~~~~^^^^^^^^^^^^^^^^^^^^^^^^^^^^^^^^^^^^^^^^\nsocket.gaierror: [Errno 11001] getaddrinfo failed\n\nThe above exception was the direct cause of the following exception:\n\nTraceback (most recent call last):\n  File \"C:\\Users\\hithesh_sunkara\\AppData\\Roaming\\Python\\Python313\\site-packages\\urllib3\\connectionpool.py\", line 787, in urlopen\n    response = self._make_request(\n        conn,\n    ...<10 lines>...\n        **response_kw,\n    )\n  File \"C:\\Users\\hithesh_sunkara\\AppData\\Roaming\\Python\\Python313\\site-packages\\urllib3\\connectionpool.py\", line 488, in _make_request\n    raise new_e\n  File \"C:\\Users\\hithesh_sunkara\\AppData\\Roaming\\Python\\Python313\\site-packages\\urllib3\\connectionpool.py\", line 464, in _make_request\n    self._validate_conn(conn)\n    ~~~~~~~~~~~~~~~~~~~^^^^^^\n  File \"C:\\Users\\hithesh_sunkara\\AppData\\Roaming\\Python\\Python313\\site-packages\\urllib3\\connectionpool.py\", line 1093, in _validate_conn\n    conn.connect()\n    ~~~~~~~~~~~~^^\n  File \"C:\\Users\\hithesh_sunkara\\AppData\\Roaming\\Python\\Python313\\site-packages\\urllib3\\connection.py\", line 704, in connect\n    self.sock = sock = self._new_conn()\n                       ~~~~~~~~~~~~~~^^\n  File \"C:\\Users\\hithesh_sunkara\\AppData\\Roaming\\Python\\Python313\\site-packages\\urllib3\\connection.py\", line 205, in _new_conn\n    raise NameResolutionError(self.host, self, e) from e\nurllib3.exceptions.NameResolutionError: <urllib3.connection.HTTPSConnection object at 0x000002084F40C910>: Failed to resolve 'api-t1.fyers.in' ([Errno 11001] getaddrinfo failed)\n\nThe above exception was the direct cause of the following exception:\n\nTraceback (most recent call last):\n  File \"C:\\Users\\hithesh_sunkara\\AppData\\Roaming\\Python\\Python313\\site-packages\\requests\\adapters.py\", line 486, in send\n    resp = conn.urlopen(\n        method=request.method,\n    ...<9 lines>...\n        chunked=chunked,\n    )\n  File \"C:\\Users\\hithesh_sunkara\\AppData\\Roaming\\Python\\Python313\\site-packages\\urllib3\\connectionpool.py\", line 841, in urlopen\n    retries = retries.increment(\n        method, url, error=new_e, _pool=self, _stacktrace=sys.exc_info()[2]\n    )\n  File \"C:\\Users\\hithesh_sunkara\\AppData\\Roaming\\Python\\Python313\\site-packages\\urllib3\\util\\retry.py\", line 519, in increment\n    raise MaxRetryError(_pool, url, reason) from reason  # type: ignore[arg-type]\n    ^^^^^^^^^^^^^^^^^^^^^^^^^^^^^^^^^^^^^^^^^^^^^^^^^^^\nurllib3.exceptions.MaxRetryError: HTTPSConnectionPool(host='api-t1.fyers.in', port=443): Max retries exceeded with url: /data/symbol-token (Caused by NameResolutionError(\"<urllib3.connection.HTTPSConnection object at 0x000002084F40C910>: Failed to resolve 'api-t1.fyers.in' ([Errno 11001] getaddrinfo failed)\"))\n\nDuring handling of the above exception, another exception occurred:\n\nTraceback (most recent call last):\n  File \"C:\\Users\\hithesh_sunkara\\AppData\\Roaming\\Python\\Python313\\site-packages\\fyers_apiv3\\FyersWebsocket\\data_ws.py\", line 63, in symbol_to_hsmtoken\n    response = requests.post(\n        url=self.symbols_token_api ,\n    ...<3 lines>...\n        },json=data\n    )\n  File \"C:\\Users\\hithesh_sunkara\\AppData\\Roaming\\Python\\Python313\\site-packages\\requests\\api.py\", line 115, in post\n    return request(\"post\", url, data=data, json=json, **kwargs)\n  File \"C:\\Users\\hithesh_sunkara\\AppData\\Roaming\\Python\\Python313\\site-packages\\requests\\api.py\", line 59, in request\n    return session.request(method=method, url=url, **kwargs)\n           ~~~~~~~~~~~~~~~^^^^^^^^^^^^^^^^^^^^^^^^^^^^^^^^^^\n  File \"C:\\Users\\hithesh_sunkara\\AppData\\Roaming\\Python\\Python313\\site-packages\\requests\\sessions.py\", line 589, in request\n    resp = self.send(prep, **send_kwargs)\n  File \"C:\\Users\\hithesh_sunkara\\AppData\\Roaming\\Python\\Python313\\site-packages\\requests\\sessions.py\", line 703, in send\n    r = adapter.send(request, **kwargs)\n  File \"C:\\Users\\hithesh_sunkara\\AppData\\Roaming\\Python\\Python313\\site-packages\\requests\\adapters.py\", line 519, in send\n    raise ConnectionError(e, request=request)\nrequests.exceptions.ConnectionError: HTTPSConnectionPool(host='api-t1.fyers.in', port=443): Max retries exceeded with url: /data/symbol-token (Caused by NameResolutionError(\"<urllib3.connection.HTTPSConnection object at 0x000002084F40C910>: Failed to resolve 'api-t1.fyers.in' ([Errno 11001] getaddrinfo failed)\"))","exception_name":"ConnectionError"}
{"level":"ERROR","location":"[__symbol_conversion:1374] data_ws","message":"'NoneType' object is not subscriptable","timestamp":"2025-05-28 22:37:40,484+0530","service":"FyersDataSocket","exception":"Traceback (most recent call last):\n  File \"C:\\Users\\hithesh_sunkara\\AppData\\Roaming\\Python\\Python313\\site-packages\\websocket\\_http.py\", line 155, in _get_addrinfo_list\n    addrinfo_list = socket.getaddrinfo(\n        hostname, port, 0, socket.SOCK_STREAM, socket.SOL_TCP)\n  File \"C:\\Python313\\Lib\\socket.py\", line 977, in getaddrinfo\n    for res in _socket.getaddrinfo(host, port, family, type, proto, flags):\n               ~~~~~~~~~~~~~~~~~~~^^^^^^^^^^^^^^^^^^^^^^^^^^^^^^^^^^^^^^^^\nsocket.gaierror: [Errno 11001] getaddrinfo failed\n\nDuring handling of the above exception, another exception occurred:\n\nTraceback (most recent call last):\n  File \"C:\\Users\\hithesh_sunkara\\AppData\\Roaming\\Python\\Python313\\site-packages\\websocket\\_app.py\", line 412, in setSock\n    self.sock.connect(\n    ~~~~~~~~~~~~~~~~~^\n        self.url, header=self.header, cookie=self.cookie,\n        ^^^^^^^^^^^^^^^^^^^^^^^^^^^^^^^^^^^^^^^^^^^^^^^^^\n    ...<4 lines>...\n        host=host, origin=origin, suppress_origin=suppress_origin,\n        ^^^^^^^^^^^^^^^^^^^^^^^^^^^^^^^^^^^^^^^^^^^^^^^^^^^^^^^^^^\n        proxy_type=proxy_type, socket=self.prepared_socket)\n        ^^^^^^^^^^^^^^^^^^^^^^^^^^^^^^^^^^^^^^^^^^^^^^^^^^^\n  File \"C:\\Users\\hithesh_sunkara\\AppData\\Roaming\\Python\\Python313\\site-packages\\websocket\\_core.py\", line 249, in connect\n    self.sock, addrs = connect(url, self.sock_opt, proxy_info(**options),\n                       ~~~~~~~^^^^^^^^^^^^^^^^^^^^^^^^^^^^^^^^^^^^^^^^^^^\n                               options.pop('socket', None))\n                               ^^^^^^^^^^^^^^^^^^^^^^^^^^^^\n  File \"C:\\Users\\hithesh_sunkara\\AppData\\Roaming\\Python\\Python313\\site-packages\\websocket\\_http.py\", line 122, in connect\n    addrinfo_list, need_tunnel, auth = _get_addrinfo_list(\n                                       ~~~~~~~~~~~~~~~~~~^\n        hostname, port_from_url, is_secure, proxy)\n        ^^^^^^^^^^^^^^^^^^^^^^^^^^^^^^^^^^^^^^^^^^\n  File \"C:\\Users\\hithesh_sunkara\\AppData\\Roaming\\Python\\Python313\\site-packages\\websocket\\_http.py\", line 167, in _get_addrinfo_list\n    raise WebSocketAddressException(e)\nwebsocket._exceptions.WebSocketAddressException: [Errno 11001] getaddrinfo failed\n\nDuring handling of the above exception, another exception occurred:\n\nTraceback (most recent call last):\n  File \"C:\\Users\\hithesh_sunkara\\AppData\\Roaming\\Python\\Python313\\site-packages\\fyers_apiv3\\FyersWebsocket\\data_ws.py\", line 1333, in __symbol_conversion\n    if symbol_value[3] != \"\":\n       ~~~~~~~~~~~~^^^\nTypeError: 'NoneType' object is not subscriptable","exception_name":"TypeError"}
{"level":"ERROR","location":"[access_token_to_hsmtoken:272] data_ws","message":{"type":"cn","code":-99,"message":"Token is expired","s":"error"},"timestamp":"2025-05-29 12:09:42,376+0530","service":"FyersDataSocket"}
{"level":"ERROR","location":"[symbol_to_hsmtoken:126] data_ws","message":"cannot access local variable 'hsm_symbol' where it is not associated with a value","timestamp":"2025-05-29 12:16:14,176+0530","service":"FyersDataSocket","exception":"Traceback (most recent call last):\n  File \"C:\\Users\\hithesh_sunkara\\AppData\\Roaming\\Python\\Python313\\site-packages\\fyers_apiv3\\FyersWebsocket\\data_ws.py\", line 115, in symbol_to_hsmtoken\n    datadict[hsm_symbol] = symbol\n             ^^^^^^^^^^\nUnboundLocalError: cannot access local variable 'hsm_symbol' where it is not associated with a value","exception_name":"UnboundLocalError"}
{"level":"ERROR","location":"[__symbol_conversion:1374] data_ws","message":"'NoneType' object is not subscriptable","timestamp":"2025-05-29 12:16:14,183+0530","service":"FyersDataSocket","exception":"Traceback (most recent call last):\n  File \"C:\\Users\\hithesh_sunkara\\AppData\\Roaming\\Python\\Python313\\site-packages\\fyers_apiv3\\FyersWebsocket\\data_ws.py\", line 1333, in __symbol_conversion\n    if symbol_value[3] != \"\":\n       ~~~~~~~~~~~~^^^\nTypeError: 'NoneType' object is not subscriptable","exception_name":"TypeError"}
{"level":"ERROR","location":"[symbol_to_hsmtoken:126] data_ws","message":"cannot access local variable 'hsm_symbol' where it is not associated with a value","timestamp":"2025-05-29 12:21:24,535+0530","service":"FyersDataSocket","exception":"Traceback (most recent call last):\n  File \"C:\\Users\\hithesh_sunkara\\AppData\\Roaming\\Python\\Python313\\site-packages\\fyers_apiv3\\FyersWebsocket\\data_ws.py\", line 115, in symbol_to_hsmtoken\n    datadict[hsm_symbol] = symbol\n             ^^^^^^^^^^\nUnboundLocalError: cannot access local variable 'hsm_symbol' where it is not associated with a value","exception_name":"UnboundLocalError"}
{"level":"ERROR","location":"[__symbol_conversion:1374] data_ws","message":"'NoneType' object is not subscriptable","timestamp":"2025-05-29 12:21:24,540+0530","service":"FyersDataSocket","exception":"Traceback (most recent call last):\n  File \"C:\\Users\\hithesh_sunkara\\AppData\\Roaming\\Python\\Python313\\site-packages\\fyers_apiv3\\FyersWebsocket\\data_ws.py\", line 1333, in __symbol_conversion\n    if symbol_value[3] != \"\":\n       ~~~~~~~~~~~~^^^\nTypeError: 'NoneType' object is not subscriptable","exception_name":"TypeError"}
{"level":"ERROR","location":"[<lambda>:1663] data_ws","message":"[WinError 10054] An existing connection was forcibly closed by the remote host","timestamp":"2025-05-29 12:40:26,246+0530","service":"FyersDataSocket"}
{"level":"ERROR","location":"[symbol_to_hsmtoken:126] data_ws","message":"cannot access local variable 'hsm_symbol' where it is not associated with a value","timestamp":"2025-05-29 12:40:34,158+0530","service":"FyersDataSocket","exception":"Traceback (most recent call last):\n  File \"C:\\Users\\hithesh_sunkara\\AppData\\Roaming\\Python\\Python313\\site-packages\\websocket\\_app.py\", line 428, in setSock\n    dispatcher.read(self.sock.sock, read, check)\n    ~~~~~~~~~~~~~~~^^^^^^^^^^^^^^^^^^^^^^^^^^^^^\n  File \"C:\\Users\\hithesh_sunkara\\AppData\\Roaming\\Python\\Python313\\site-packages\\websocket\\_app.py\", line 99, in read\n    if not read_callback():\n           ~~~~~~~~~~~~~^^\n  File \"C:\\Users\\hithesh_sunkara\\AppData\\Roaming\\Python\\Python313\\site-packages\\websocket\\_app.py\", line 437, in read\n    op_code, frame = self.sock.recv_data_frame(True)\n                     ~~~~~~~~~~~~~~~~~~~~~~~~~^^^^^^\n  File \"C:\\Users\\hithesh_sunkara\\AppData\\Roaming\\Python\\Python313\\site-packages\\websocket\\_core.py\", line 406, in recv_data_frame\n    frame = self.recv_frame()\n  File \"C:\\Users\\hithesh_sunkara\\AppData\\Roaming\\Python\\Python313\\site-packages\\websocket\\_core.py\", line 445, in recv_frame\n    return self.frame_buffer.recv_frame()\n           ~~~~~~~~~~~~~~~~~~~~~~~~~~~~^^\n  File \"C:\\Users\\hithesh_sunkara\\AppData\\Roaming\\Python\\Python313\\site-packages\\websocket\\_abnf.py\", line 338, in recv_frame\n    self.recv_header()\n    ~~~~~~~~~~~~~~~~^^\n  File \"C:\\Users\\hithesh_sunkara\\AppData\\Roaming\\Python\\Python313\\site-packages\\websocket\\_abnf.py\", line 294, in recv_header\n    header = self.recv_strict(2)\n  File \"C:\\Users\\hithesh_sunkara\\AppData\\Roaming\\Python\\Python313\\site-packages\\websocket\\_abnf.py\", line 373, in recv_strict\n    bytes_ = self.recv(min(16384, shortage))\n  File \"C:\\Users\\hithesh_sunkara\\AppData\\Roaming\\Python\\Python313\\site-packages\\websocket\\_core.py\", line 529, in _recv\n    return recv(self.sock, bufsize)\n  File \"C:\\Users\\hithesh_sunkara\\AppData\\Roaming\\Python\\Python313\\site-packages\\websocket\\_socket.py\", line 108, in recv\n    bytes_ = _recv()\n  File \"C:\\Users\\hithesh_sunkara\\AppData\\Roaming\\Python\\Python313\\site-packages\\websocket\\_socket.py\", line 87, in _recv\n    return sock.recv(bufsize)\n           ~~~~~~~~~^^^^^^^^^\n  File \"C:\\Python313\\Lib\\ssl.py\", line 1285, in recv\n    return self.read(buflen)\n           ~~~~~~~~~^^^^^^^^\n  File \"C:\\Python313\\Lib\\ssl.py\", line 1140, in read\n    return self._sslobj.read(len)\n           ~~~~~~~~~~~~~~~~~^^^^^\nConnectionResetError: [WinError 10054] An existing connection was forcibly closed by the remote host\n\nDuring handling of the above exception, another exception occurred:\n\nTraceback (most recent call last):\n  File \"C:\\Users\\hithesh_sunkara\\AppData\\Roaming\\Python\\Python313\\site-packages\\fyers_apiv3\\FyersWebsocket\\data_ws.py\", line 115, in symbol_to_hsmtoken\n    datadict[hsm_symbol] = symbol\n             ^^^^^^^^^^\nUnboundLocalError: cannot access local variable 'hsm_symbol' where it is not associated with a value","exception_name":"UnboundLocalError"}
{"level":"ERROR","location":"[__symbol_conversion:1374] data_ws","message":"'NoneType' object is not subscriptable","timestamp":"2025-05-29 12:40:34,173+0530","service":"FyersDataSocket","exception":"Traceback (most recent call last):\n  File \"C:\\Users\\hithesh_sunkara\\AppData\\Roaming\\Python\\Python313\\site-packages\\websocket\\_app.py\", line 428, in setSock\n    dispatcher.read(self.sock.sock, read, check)\n    ~~~~~~~~~~~~~~~^^^^^^^^^^^^^^^^^^^^^^^^^^^^^\n  File \"C:\\Users\\hithesh_sunkara\\AppData\\Roaming\\Python\\Python313\\site-packages\\websocket\\_app.py\", line 99, in read\n    if not read_callback():\n           ~~~~~~~~~~~~~^^\n  File \"C:\\Users\\hithesh_sunkara\\AppData\\Roaming\\Python\\Python313\\site-packages\\websocket\\_app.py\", line 437, in read\n    op_code, frame = self.sock.recv_data_frame(True)\n                     ~~~~~~~~~~~~~~~~~~~~~~~~~^^^^^^\n  File \"C:\\Users\\hithesh_sunkara\\AppData\\Roaming\\Python\\Python313\\site-packages\\websocket\\_core.py\", line 406, in recv_data_frame\n    frame = self.recv_frame()\n  File \"C:\\Users\\hithesh_sunkara\\AppData\\Roaming\\Python\\Python313\\site-packages\\websocket\\_core.py\", line 445, in recv_frame\n    return self.frame_buffer.recv_frame()\n           ~~~~~~~~~~~~~~~~~~~~~~~~~~~~^^\n  File \"C:\\Users\\hithesh_sunkara\\AppData\\Roaming\\Python\\Python313\\site-packages\\websocket\\_abnf.py\", line 338, in recv_frame\n    self.recv_header()\n    ~~~~~~~~~~~~~~~~^^\n  File \"C:\\Users\\hithesh_sunkara\\AppData\\Roaming\\Python\\Python313\\site-packages\\websocket\\_abnf.py\", line 294, in recv_header\n    header = self.recv_strict(2)\n  File \"C:\\Users\\hithesh_sunkara\\AppData\\Roaming\\Python\\Python313\\site-packages\\websocket\\_abnf.py\", line 373, in recv_strict\n    bytes_ = self.recv(min(16384, shortage))\n  File \"C:\\Users\\hithesh_sunkara\\AppData\\Roaming\\Python\\Python313\\site-packages\\websocket\\_core.py\", line 529, in _recv\n    return recv(self.sock, bufsize)\n  File \"C:\\Users\\hithesh_sunkara\\AppData\\Roaming\\Python\\Python313\\site-packages\\websocket\\_socket.py\", line 108, in recv\n    bytes_ = _recv()\n  File \"C:\\Users\\hithesh_sunkara\\AppData\\Roaming\\Python\\Python313\\site-packages\\websocket\\_socket.py\", line 87, in _recv\n    return sock.recv(bufsize)\n           ~~~~~~~~~^^^^^^^^^\n  File \"C:\\Python313\\Lib\\ssl.py\", line 1285, in recv\n    return self.read(buflen)\n           ~~~~~~~~~^^^^^^^^\n  File \"C:\\Python313\\Lib\\ssl.py\", line 1140, in read\n    return self._sslobj.read(len)\n           ~~~~~~~~~~~~~~~~~^^^^^\nConnectionResetError: [WinError 10054] An existing connection was forcibly closed by the remote host\n\nDuring handling of the above exception, another exception occurred:\n\nTraceback (most recent call last):\n  File \"C:\\Users\\hithesh_sunkara\\AppData\\Roaming\\Python\\Python313\\site-packages\\fyers_apiv3\\FyersWebsocket\\data_ws.py\", line 1333, in __symbol_conversion\n    if symbol_value[3] != \"\":\n       ~~~~~~~~~~~~^^^\nTypeError: 'NoneType' object is not subscriptable","exception_name":"TypeError"}
{"level":"ERROR","location":"[on_open:1519] data_ws","message":"'FyersModel' object has no attribute 'subscribe'","timestamp":"2025-05-29 14:12:13,564+0530","service":"FyersDataSocket","exception":"Traceback (most recent call last):\n  File \"C:\\Users\\hithesh_sunkara\\AppData\\Roaming\\Python\\Python313\\site-packages\\fyers_apiv3\\FyersWebsocket\\data_ws.py\", line 1517, in on_open\n    self.OnOpen()\n    ~~~~~~~~~~~^^\n  File \"C:\\Users\\hithesh_sunkara\\Desktop\\personal\\fyers bot\\fyers_ops.py\", line 82, in onopen\n    fyers.subscribe(symbols=symbols, data_type=data_type)\n    ^^^^^^^^^^^^^^^\nAttributeError: 'FyersModel' object has no attribute 'subscribe'","exception_name":"AttributeError"}
{"level":"ERROR","location":"[on_open:1520] data_ws","message":"'FyersModel' object has no attribute 'subscribe'","timestamp":"2025-05-29 14:12:13,568+0530","service":"FyersDataSocket"}
{"level":"ERROR","location":"[on_open:1519] data_ws","message":"onopen() missing 1 required positional argument: 'ws'","timestamp":"2025-05-29 15:00:17,574+0530","service":"FyersDataSocket","exception":"Traceback (most recent call last):\n  File \"C:\\Users\\hithesh_sunkara\\AppData\\Roaming\\Python\\Python313\\site-packages\\fyers_apiv3\\FyersWebsocket\\data_ws.py\", line 1517, in on_open\n    self.OnOpen()\n    ~~~~~~~~~~~^^\nTypeError: onopen() missing 1 required positional argument: 'ws'","exception_name":"TypeError"}
{"level":"ERROR","location":"[on_open:1520] data_ws","message":"onopen() missing 1 required positional argument: 'ws'","timestamp":"2025-05-29 15:00:17,576+0530","service":"FyersDataSocket"}
{"level":"ERROR","location":"[on_open:1519] data_ws","message":"onopen() missing 1 required positional argument: 'ws'","timestamp":"2025-05-29 15:02:00,355+0530","service":"FyersDataSocket","exception":"Traceback (most recent call last):\n  File \"C:\\Users\\hithesh_sunkara\\AppData\\Roaming\\Python\\Python313\\site-packages\\fyers_apiv3\\FyersWebsocket\\data_ws.py\", line 1517, in on_open\n    self.OnOpen()\n    ~~~~~~~~~~~^^\nTypeError: onopen() missing 1 required positional argument: 'ws'","exception_name":"TypeError"}
{"level":"ERROR","location":"[on_open:1520] data_ws","message":"onopen() missing 1 required positional argument: 'ws'","timestamp":"2025-05-29 15:02:00,358+0530","service":"FyersDataSocket"}
{"level":"ERROR","location":"[on_open:1519] data_ws","message":"on_open() missing 1 required positional argument: 'ws'","timestamp":"2025-05-29 15:09:20,805+0530","service":"FyersDataSocket","exception":"Traceback (most recent call last):\n  File \"C:\\Users\\hithesh_sunkara\\AppData\\Roaming\\Python\\Python313\\site-packages\\fyers_apiv3\\FyersWebsocket\\data_ws.py\", line 1517, in on_open\n    self.OnOpen()\n    ~~~~~~~~~~~^^\nTypeError: on_open() missing 1 required positional argument: 'ws'","exception_name":"TypeError"}
{"level":"ERROR","location":"[on_open:1520] data_ws","message":"on_open() missing 1 required positional argument: 'ws'","timestamp":"2025-05-29 15:09:20,806+0530","service":"FyersDataSocket"}
{"level":"ERROR","location":"[<lambda>:1663] data_ws","message":"[WinError 10054] An existing connection was forcibly closed by the remote host","timestamp":"2025-05-30 14:27:30,158+0530","service":"FyersDataSocket"}
{"level":"ERROR","location":"[<lambda>:1663] data_ws","message":"[Errno 11001] getaddrinfo failed","timestamp":"2025-05-30 15:30:04,893+0530","service":"FyersDataSocket"}
{"level":"ERROR","location":"[symbol_to_hsmtoken:126] data_ws","message":"HTTPSConnectionPool(host='api-t1.fyers.in', port=443): Max retries exceeded with url: /data/symbol-token (Caused by NameResolutionError(\"<urllib3.connection.HTTPSConnection object at 0x000001759DDCC190>: Failed to resolve 'api-t1.fyers.in' ([Errno 11001] getaddrinfo failed)\"))","timestamp":"2025-05-30 15:30:06,891+0530","service":"FyersDataSocket","exception":"Traceback (most recent call last):\n  File \"C:\\Users\\hithesh_sunkara\\AppData\\Roaming\\Python\\Python313\\site-packages\\websocket\\_app.py\", line 428, in setSock\n    dispatcher.read(self.sock.sock, read, check)\n    ~~~~~~~~~~~~~~~^^^^^^^^^^^^^^^^^^^^^^^^^^^^^\n  File \"C:\\Users\\hithesh_sunkara\\AppData\\Roaming\\Python\\Python313\\site-packages\\websocket\\_app.py\", line 99, in read\n    if not read_callback():\n           ~~~~~~~~~~~~~^^\n  File \"C:\\Users\\hithesh_sunkara\\AppData\\Roaming\\Python\\Python313\\site-packages\\websocket\\_app.py\", line 437, in read\n    op_code, frame = self.sock.recv_data_frame(True)\n                     ~~~~~~~~~~~~~~~~~~~~~~~~~^^^^^^\n  File \"C:\\Users\\hithesh_sunkara\\AppData\\Roaming\\Python\\Python313\\site-packages\\websocket\\_core.py\", line 406, in recv_data_frame\n    frame = self.recv_frame()\n  File \"C:\\Users\\hithesh_sunkara\\AppData\\Roaming\\Python\\Python313\\site-packages\\websocket\\_core.py\", line 445, in recv_frame\n    return self.frame_buffer.recv_frame()\n           ~~~~~~~~~~~~~~~~~~~~~~~~~~~~^^\n  File \"C:\\Users\\hithesh_sunkara\\AppData\\Roaming\\Python\\Python313\\site-packages\\websocket\\_abnf.py\", line 338, in recv_frame\n    self.recv_header()\n    ~~~~~~~~~~~~~~~~^^\n  File \"C:\\Users\\hithesh_sunkara\\AppData\\Roaming\\Python\\Python313\\site-packages\\websocket\\_abnf.py\", line 294, in recv_header\n    header = self.recv_strict(2)\n  File \"C:\\Users\\hithesh_sunkara\\AppData\\Roaming\\Python\\Python313\\site-packages\\websocket\\_abnf.py\", line 373, in recv_strict\n    bytes_ = self.recv(min(16384, shortage))\n  File \"C:\\Users\\hithesh_sunkara\\AppData\\Roaming\\Python\\Python313\\site-packages\\websocket\\_core.py\", line 529, in _recv\n    return recv(self.sock, bufsize)\n  File \"C:\\Users\\hithesh_sunkara\\AppData\\Roaming\\Python\\Python313\\site-packages\\websocket\\_socket.py\", line 108, in recv\n    bytes_ = _recv()\n  File \"C:\\Users\\hithesh_sunkara\\AppData\\Roaming\\Python\\Python313\\site-packages\\websocket\\_socket.py\", line 87, in _recv\n    return sock.recv(bufsize)\n           ~~~~~~~~~^^^^^^^^^\n  File \"C:\\Python313\\Lib\\ssl.py\", line 1285, in recv\n    return self.read(buflen)\n           ~~~~~~~~~^^^^^^^^\n  File \"C:\\Python313\\Lib\\ssl.py\", line 1140, in read\n    return self._sslobj.read(len)\n           ~~~~~~~~~~~~~~~~~^^^^^\nConnectionResetError: [WinError 10054] An existing connection was forcibly closed by the remote host\n\nDuring handling of the above exception, another exception occurred:\n\nTraceback (most recent call last):\n  File \"C:\\Users\\hithesh_sunkara\\AppData\\Roaming\\Python\\Python313\\site-packages\\urllib3\\connection.py\", line 198, in _new_conn\n    sock = connection.create_connection(\n        (self._dns_host, self.port),\n    ...<2 lines>...\n        socket_options=self.socket_options,\n    )\n  File \"C:\\Users\\hithesh_sunkara\\AppData\\Roaming\\Python\\Python313\\site-packages\\urllib3\\util\\connection.py\", line 60, in create_connection\n    for res in socket.getaddrinfo(host, port, family, socket.SOCK_STREAM):\n               ~~~~~~~~~~~~~~~~~~^^^^^^^^^^^^^^^^^^^^^^^^^^^^^^^^^^^^^^^^\n  File \"C:\\Python313\\Lib\\socket.py\", line 977, in getaddrinfo\n    for res in _socket.getaddrinfo(host, port, family, type, proto, flags):\n               ~~~~~~~~~~~~~~~~~~~^^^^^^^^^^^^^^^^^^^^^^^^^^^^^^^^^^^^^^^^\nsocket.gaierror: [Errno 11001] getaddrinfo failed\n\nThe above exception was the direct cause of the following exception:\n\nTraceback (most recent call last):\n  File \"C:\\Users\\hithesh_sunkara\\AppData\\Roaming\\Python\\Python313\\site-packages\\urllib3\\connectionpool.py\", line 787, in urlopen\n    response = self._make_request(\n        conn,\n    ...<10 lines>...\n        **response_kw,\n    )\n  File \"C:\\Users\\hithesh_sunkara\\AppData\\Roaming\\Python\\Python313\\site-packages\\urllib3\\connectionpool.py\", line 488, in _make_request\n    raise new_e\n  File \"C:\\Users\\hithesh_sunkara\\AppData\\Roaming\\Python\\Python313\\site-packages\\urllib3\\connectionpool.py\", line 464, in _make_request\n    self._validate_conn(conn)\n    ~~~~~~~~~~~~~~~~~~~^^^^^^\n  File \"C:\\Users\\hithesh_sunkara\\AppData\\Roaming\\Python\\Python313\\site-packages\\urllib3\\connectionpool.py\", line 1093, in _validate_conn\n    conn.connect()\n    ~~~~~~~~~~~~^^\n  File \"C:\\Users\\hithesh_sunkara\\AppData\\Roaming\\Python\\Python313\\site-packages\\urllib3\\connection.py\", line 704, in connect\n    self.sock = sock = self._new_conn()\n                       ~~~~~~~~~~~~~~^^\n  File \"C:\\Users\\hithesh_sunkara\\AppData\\Roaming\\Python\\Python313\\site-packages\\urllib3\\connection.py\", line 205, in _new_conn\n    raise NameResolutionError(self.host, self, e) from e\nurllib3.exceptions.NameResolutionError: <urllib3.connection.HTTPSConnection object at 0x000001759DDCC190>: Failed to resolve 'api-t1.fyers.in' ([Errno 11001] getaddrinfo failed)\n\nThe above exception was the direct cause of the following exception:\n\nTraceback (most recent call last):\n  File \"C:\\Users\\hithesh_sunkara\\AppData\\Roaming\\Python\\Python313\\site-packages\\requests\\adapters.py\", line 486, in send\n    resp = conn.urlopen(\n        method=request.method,\n    ...<9 lines>...\n        chunked=chunked,\n    )\n  File \"C:\\Users\\hithesh_sunkara\\AppData\\Roaming\\Python\\Python313\\site-packages\\urllib3\\connectionpool.py\", line 841, in urlopen\n    retries = retries.increment(\n        method, url, error=new_e, _pool=self, _stacktrace=sys.exc_info()[2]\n    )\n  File \"C:\\Users\\hithesh_sunkara\\AppData\\Roaming\\Python\\Python313\\site-packages\\urllib3\\util\\retry.py\", line 519, in increment\n    raise MaxRetryError(_pool, url, reason) from reason  # type: ignore[arg-type]\n    ^^^^^^^^^^^^^^^^^^^^^^^^^^^^^^^^^^^^^^^^^^^^^^^^^^^\nurllib3.exceptions.MaxRetryError: HTTPSConnectionPool(host='api-t1.fyers.in', port=443): Max retries exceeded with url: /data/symbol-token (Caused by NameResolutionError(\"<urllib3.connection.HTTPSConnection object at 0x000001759DDCC190>: Failed to resolve 'api-t1.fyers.in' ([Errno 11001] getaddrinfo failed)\"))\n\nDuring handling of the above exception, another exception occurred:\n\nTraceback (most recent call last):\n  File \"C:\\Users\\hithesh_sunkara\\AppData\\Roaming\\Python\\Python313\\site-packages\\fyers_apiv3\\FyersWebsocket\\data_ws.py\", line 63, in symbol_to_hsmtoken\n    response = requests.post(\n        url=self.symbols_token_api ,\n    ...<3 lines>...\n        },json=data\n    )\n  File \"C:\\Users\\hithesh_sunkara\\AppData\\Roaming\\Python\\Python313\\site-packages\\requests\\api.py\", line 115, in post\n    return request(\"post\", url, data=data, json=json, **kwargs)\n  File \"C:\\Users\\hithesh_sunkara\\AppData\\Roaming\\Python\\Python313\\site-packages\\requests\\api.py\", line 59, in request\n    return session.request(method=method, url=url, **kwargs)\n           ~~~~~~~~~~~~~~~^^^^^^^^^^^^^^^^^^^^^^^^^^^^^^^^^^\n  File \"C:\\Users\\hithesh_sunkara\\AppData\\Roaming\\Python\\Python313\\site-packages\\requests\\sessions.py\", line 589, in request\n    resp = self.send(prep, **send_kwargs)\n  File \"C:\\Users\\hithesh_sunkara\\AppData\\Roaming\\Python\\Python313\\site-packages\\requests\\sessions.py\", line 703, in send\n    r = adapter.send(request, **kwargs)\n  File \"C:\\Users\\hithesh_sunkara\\AppData\\Roaming\\Python\\Python313\\site-packages\\requests\\adapters.py\", line 519, in send\n    raise ConnectionError(e, request=request)\nrequests.exceptions.ConnectionError: HTTPSConnectionPool(host='api-t1.fyers.in', port=443): Max retries exceeded with url: /data/symbol-token (Caused by NameResolutionError(\"<urllib3.connection.HTTPSConnection object at 0x000001759DDCC190>: Failed to resolve 'api-t1.fyers.in' ([Errno 11001] getaddrinfo failed)\"))","exception_name":"ConnectionError"}
{"level":"ERROR","location":"[__symbol_conversion:1374] data_ws","message":"'NoneType' object is not subscriptable","timestamp":"2025-05-30 15:30:06,913+0530","service":"FyersDataSocket","exception":"Traceback (most recent call last):\n  File \"C:\\Users\\hithesh_sunkara\\AppData\\Roaming\\Python\\Python313\\site-packages\\websocket\\_app.py\", line 428, in setSock\n    dispatcher.read(self.sock.sock, read, check)\n    ~~~~~~~~~~~~~~~^^^^^^^^^^^^^^^^^^^^^^^^^^^^^\n  File \"C:\\Users\\hithesh_sunkara\\AppData\\Roaming\\Python\\Python313\\site-packages\\websocket\\_app.py\", line 99, in read\n    if not read_callback():\n           ~~~~~~~~~~~~~^^\n  File \"C:\\Users\\hithesh_sunkara\\AppData\\Roaming\\Python\\Python313\\site-packages\\websocket\\_app.py\", line 437, in read\n    op_code, frame = self.sock.recv_data_frame(True)\n                     ~~~~~~~~~~~~~~~~~~~~~~~~~^^^^^^\n  File \"C:\\Users\\hithesh_sunkara\\AppData\\Roaming\\Python\\Python313\\site-packages\\websocket\\_core.py\", line 406, in recv_data_frame\n    frame = self.recv_frame()\n  File \"C:\\Users\\hithesh_sunkara\\AppData\\Roaming\\Python\\Python313\\site-packages\\websocket\\_core.py\", line 445, in recv_frame\n    return self.frame_buffer.recv_frame()\n           ~~~~~~~~~~~~~~~~~~~~~~~~~~~~^^\n  File \"C:\\Users\\hithesh_sunkara\\AppData\\Roaming\\Python\\Python313\\site-packages\\websocket\\_abnf.py\", line 338, in recv_frame\n    self.recv_header()\n    ~~~~~~~~~~~~~~~~^^\n  File \"C:\\Users\\hithesh_sunkara\\AppData\\Roaming\\Python\\Python313\\site-packages\\websocket\\_abnf.py\", line 294, in recv_header\n    header = self.recv_strict(2)\n  File \"C:\\Users\\hithesh_sunkara\\AppData\\Roaming\\Python\\Python313\\site-packages\\websocket\\_abnf.py\", line 373, in recv_strict\n    bytes_ = self.recv(min(16384, shortage))\n  File \"C:\\Users\\hithesh_sunkara\\AppData\\Roaming\\Python\\Python313\\site-packages\\websocket\\_core.py\", line 529, in _recv\n    return recv(self.sock, bufsize)\n  File \"C:\\Users\\hithesh_sunkara\\AppData\\Roaming\\Python\\Python313\\site-packages\\websocket\\_socket.py\", line 108, in recv\n    bytes_ = _recv()\n  File \"C:\\Users\\hithesh_sunkara\\AppData\\Roaming\\Python\\Python313\\site-packages\\websocket\\_socket.py\", line 87, in _recv\n    return sock.recv(bufsize)\n           ~~~~~~~~~^^^^^^^^^\n  File \"C:\\Python313\\Lib\\ssl.py\", line 1285, in recv\n    return self.read(buflen)\n           ~~~~~~~~~^^^^^^^^\n  File \"C:\\Python313\\Lib\\ssl.py\", line 1140, in read\n    return self._sslobj.read(len)\n           ~~~~~~~~~~~~~~~~~^^^^^\nConnectionResetError: [WinError 10054] An existing connection was forcibly closed by the remote host\n\nDuring handling of the above exception, another exception occurred:\n\nTraceback (most recent call last):\n  File \"C:\\Users\\hithesh_sunkara\\AppData\\Roaming\\Python\\Python313\\site-packages\\fyers_apiv3\\FyersWebsocket\\data_ws.py\", line 1333, in __symbol_conversion\n    if symbol_value[3] != \"\":\n       ~~~~~~~~~~~~^^^\nTypeError: 'NoneType' object is not subscriptable","exception_name":"TypeError"}
